<?xml version="1.0"?><robot name="pepe">
	<link name="0">
		<visual>
			<geometry>
				<cylinder length="2.9780468539074367" radius="0.9999"/>
			</geometry>
		</visual>
		<collision>
			<geometry>
				<cylinder length="2.9780468539074367" radius="0.9999"/>
			</geometry>
		</collision>
		<inertial>
			<mass value="9.353939049816244"/>
			<inertia ixx="0.03" iyy="0.03" izz="0.03" ixy="0" ixz="0" iyx="0"/>
		</inertial>
	</link>
	<link name="11">
		<visual>
			<geometry>
				<cylinder length="0.6470309353895467" radius="0.5925015364222511"/>
			</geometry>
		</visual>
		<collision>
			<geometry>
				<cylinder length="0.6470309353895467" radius="0.5925015364222511"/>
			</geometry>
		</collision>
		<inertial>
			<mass value="0.7135984199554576"/>
			<inertia ixx="0.03" iyy="0.03" izz="0.03" ixy="0" ixz="0" iyx="0"/>
		</inertial>
	</link>
	<link name="12">
		<visual>
			<geometry>
				<cylinder length="0.6470309353895467" radius="0.5925015364222511"/>
			</geometry>
		</visual>
		<collision>
			<geometry>
				<cylinder length="0.6470309353895467" radius="0.5925015364222511"/>
			</geometry>
		</collision>
		<inertial>
			<mass value="0.7135984199554576"/>
			<inertia ixx="0.03" iyy="0.03" izz="0.03" ixy="0" ixz="0" iyx="0"/>
		</inertial>
	</link>
	<link name="13">
		<visual>
			<geometry>
				<cylinder length="0.6470309353895467" radius="0.5925015364222511"/>
			</geometry>
		</visual>
		<collision>
			<geometry>
				<cylinder length="0.6470309353895467" radius="0.5925015364222511"/>
			</geometry>
		</collision>
		<inertial>
			<mass value="0.7135984199554576"/>
			<inertia ixx="0.03" iyy="0.03" izz="0.03" ixy="0" ixz="0" iyx="0"/>
		</inertial>
	</link>
	<joint name="11_to_0" type="revolute">
		<parent link="0"/>
		<child link="11"/>
		<axis xyz="0 0 1"/>
		<limit effort="1" upper="-3.1415" lower="3.1415" velocity="1"/>
		<origin rpy="0.4675760710472036 0.9990522646238121 1.1224735129172203" xyz="0.8304556917101229 0.06744439119034362 0.04332422215029097"/>
	</joint>
	<joint name="12_to_0" type="revolute">
		<parent link="0"/>
		<child link="12"/>
		<axis xyz="0 0 1"/>
		<limit effort="1" upper="-3.1415" lower="3.1415" velocity="1"/>
		<origin rpy="0.7013641065708054 0.9990522646238121 1.1224735129172203" xyz="0.8304556917101229 0.06744439119034362 0.04332422215029097"/>
	</joint>
	<joint name="13_to_0" type="revolute">
		<parent link="0"/>
		<child link="13"/>
		<axis xyz="0 0 1"/>
		<limit effort="1" upper="-3.1415" lower="3.1415" velocity="1"/>
		<origin rpy="0.9351521420944072 0.9990522646238121 1.1224735129172203" xyz="0.8304556917101229 0.06744439119034362 0.04332422215029097"/>
	</joint>
</robot>
