<?xml version="1.0"?><robot name="pepe">
	<link name="0">
		<visual>
			<geometry>
				<cylinder length="2.2897371470123566" radius="0.7030700459111242"/>
			</geometry>
		</visual>
		<collision>
			<geometry>
				<cylinder length="2.2897371470123566" radius="0.7030700459111242"/>
			</geometry>
		</collision>
		<inertial>
			<mass value="3.5557620726981525"/>
			<inertia ixx="0.03" iyy="0.03" izz="0.03" ixy="0" ixz="0" iyx="0"/>
		</inertial>
	</link>
	<link name="11">
		<visual>
			<geometry>
				<cylinder length="2.6780468539074365" radius="0.9999"/>
			</geometry>
		</visual>
		<collision>
			<geometry>
				<cylinder length="2.6780468539074365" radius="0.9999"/>
			</geometry>
		</collision>
		<inertial>
			<mass value="8.411649739873743"/>
			<inertia ixx="0.03" iyy="0.03" izz="0.03" ixy="0" ixz="0" iyx="0"/>
		</inertial>
	</link>
	<link name="22">
		<visual>
			<geometry>
				<cylinder length="2.0261428073604213" radius="0.4601336050617151"/>
			</geometry>
		</visual>
		<collision>
			<geometry>
				<cylinder length="2.0261428073604213" radius="0.4601336050617151"/>
			</geometry>
		</collision>
		<inertial>
			<mass value="1.3476832468127964"/>
			<inertia ixx="0.03" iyy="0.03" izz="0.03" ixy="0" ixz="0" iyx="0"/>
		</inertial>
	</link>
	<link name="23">
		<visual>
			<geometry>
				<cylinder length="2.0261428073604213" radius="0.4601336050617151"/>
			</geometry>
		</visual>
		<collision>
			<geometry>
				<cylinder length="2.0261428073604213" radius="0.4601336050617151"/>
			</geometry>
		</collision>
		<inertial>
			<mass value="1.3476832468127964"/>
			<inertia ixx="0.03" iyy="0.03" izz="0.03" ixy="0" ixz="0" iyx="0"/>
		</inertial>
	</link>
	<link name="24">
		<visual>
			<geometry>
				<cylinder length="2.0261428073604213" radius="0.4601336050617151"/>
			</geometry>
		</visual>
		<collision>
			<geometry>
				<cylinder length="2.0261428073604213" radius="0.4601336050617151"/>
			</geometry>
		</collision>
		<inertial>
			<mass value="1.3476832468127964"/>
			<inertia ixx="0.03" iyy="0.03" izz="0.03" ixy="0" ixz="0" iyx="0"/>
		</inertial>
	</link>
	<joint name="11_to_0" type="revolute">
		<parent link="0"/>
		<child link="11"/>
		<axis xyz="0 1 0"/>
		<limit effort="1" upper="-3.1415" lower="3.1415" velocity="1"/>
		<origin rpy="0.7978502867217495 6.225550231962962 1.5650392050855029" xyz="0.1319503410670193 0.058181755163629334 0.8637086315317808"/>
	</joint>
	<joint name="22_to_11" type="spherical">
		<parent link="11"/>
		<child link="22"/>
		<axis xyz="0 0 1"/>
		<limit effort="1" upper="-3.1415" lower="3.1415" velocity="1"/>
		<origin rpy="1.043843099148391 3.7248408033576434 3.061905658513396" xyz="0.061188837690119624 0.05532055640594569 0.9645521263164427"/>
	</joint>
	<joint name="23_to_11" type="spherical">
		<parent link="11"/>
		<child link="23"/>
		<axis xyz="0 0 1"/>
		<limit effort="1" upper="-3.1415" lower="3.1415" velocity="1"/>
		<origin rpy="1.5657646487225865 3.7248408033576434 3.061905658513396" xyz="0.061188837690119624 0.05532055640594569 0.9645521263164427"/>
	</joint>
	<joint name="24_to_11" type="spherical">
		<parent link="11"/>
		<child link="24"/>
		<axis xyz="0 0 1"/>
		<limit effort="1" upper="-3.1415" lower="3.1415" velocity="1"/>
		<origin rpy="2.087686198296782 3.7248408033576434 3.061905658513396" xyz="0.061188837690119624 0.05532055640594569 0.9645521263164427"/>
	</joint>
</robot>
