<?xml version="1.0"?><robot name="pepe">
	<link name="0">
		<visual>
			<geometry>
				<cylinder length="2.9780468539074367" radius="0.9999"/>
			</geometry>
		</visual>
		<collision>
			<geometry>
				<cylinder length="2.9780468539074367" radius="0.9999"/>
			</geometry>
		</collision>
		<inertial>
			<mass value="9.353939049816244"/>
			<inertia ixx="0.03" iyy="0.03" izz="0.03" ixy="0" ixz="0" iyx="0"/>
		</inertial>
	</link>
	<link name="11">
		<visual>
			<geometry>
				<cylinder length="1.4784806233442744" radius="0.8743447457285577"/>
			</geometry>
		</visual>
		<collision>
			<geometry>
				<cylinder length="1.4784806233442744" radius="0.8743447457285577"/>
			</geometry>
		</collision>
		<inertial>
			<mass value="3.550838490425051"/>
			<inertia ixx="0.03" iyy="0.03" izz="0.03" ixy="0" ixz="0" iyx="0"/>
		</inertial>
	</link>
	<link name="12">
		<visual>
			<geometry>
				<cylinder length="1.4784806233442744" radius="0.8743447457285577"/>
			</geometry>
		</visual>
		<collision>
			<geometry>
				<cylinder length="1.4784806233442744" radius="0.8743447457285577"/>
			</geometry>
		</collision>
		<inertial>
			<mass value="3.550838490425051"/>
			<inertia ixx="0.03" iyy="0.03" izz="0.03" ixy="0" ixz="0" iyx="0"/>
		</inertial>
	</link>
	<link name="13">
		<visual>
			<geometry>
				<cylinder length="1.4784806233442744" radius="0.8743447457285577"/>
			</geometry>
		</visual>
		<collision>
			<geometry>
				<cylinder length="1.4784806233442744" radius="0.8743447457285577"/>
			</geometry>
		</collision>
		<inertial>
			<mass value="3.550838490425051"/>
			<inertia ixx="0.03" iyy="0.03" izz="0.03" ixy="0" ixz="0" iyx="0"/>
		</inertial>
	</link>
	<joint name="11_to_0" type="revolute">
		<parent link="0"/>
		<child link="11"/>
		<axis xyz="1 0 0"/>
		<limit effort="1" upper="-3.1415" lower="3.1415" velocity="1"/>
		<origin rpy="8.669224950284402 1.7331183500031386 3.3320973687835114" xyz="0.4261093969743759 0.767508247320206 0.08860544743694432"/>
	</joint>
	<joint name="12_to_0" type="revolute">
		<parent link="0"/>
		<child link="12"/>
		<axis xyz="1 0 0"/>
		<limit effort="1" upper="-3.1415" lower="3.1415" velocity="1"/>
		<origin rpy="13.003837425426603 1.7331183500031386 3.3320973687835114" xyz="0.4261093969743759 0.767508247320206 0.08860544743694432"/>
	</joint>
	<joint name="13_to_0" type="revolute">
		<parent link="0"/>
		<child link="13"/>
		<axis xyz="1 0 0"/>
		<limit effort="1" upper="-3.1415" lower="3.1415" velocity="1"/>
		<origin rpy="17.338449900568804 1.7331183500031386 3.3320973687835114" xyz="0.4261093969743759 0.767508247320206 0.08860544743694432"/>
	</joint>
</robot>
