<?xml version="1.0"?><robot name="pepe">
	<link name="0">
		<visual>
			<geometry>
				<cylinder length="2.052335271366942" radius="0.9127046226389154"/>
			</geometry>
		</visual>
		<collision>
			<geometry>
				<cylinder length="2.052335271366942" radius="0.9127046226389154"/>
			</geometry>
		</collision>
		<inertial>
			<mass value="5.371043651051132"/>
			<inertia ixx="0.03" iyy="0.03" izz="0.03" ixy="0" ixz="0" iyx="0"/>
		</inertial>
	</link>
	<link name="11">
		<visual>
			<geometry>
				<cylinder length="0.5290372595159363" radius="0.19861774505186824"/>
			</geometry>
		</visual>
		<collision>
			<geometry>
				<cylinder length="0.5290372595159363" radius="0.19861774505186824"/>
			</geometry>
		</collision>
		<inertial>
			<mass value="0.06556502431248978"/>
			<inertia ixx="0.03" iyy="0.03" izz="0.03" ixy="0" ixz="0" iyx="0"/>
		</inertial>
	</link>
	<joint name="11_to_0" type="revolute">
		<parent link="0"/>
		<child link="11"/>
		<axis xyz="0 1 0"/>
		<limit effort="1" upper="-3.1415" lower="3.1415" velocity="1"/>
		<origin rpy="3.560542831227465 1.8367374741055937 3.2082933823085913" xyz="0.6316240809060147 0.39293720338173266 0.18021499848701328"/>
	</joint>
</robot>
