<?xml version="1.0"?><robot name="pepe">
	<link name="0">
		<visual>
			<geometry>
				<cylinder length="2.8219324425915286" radius="0.2802727606231159"/>
			</geometry>
		</visual>
		<collision>
			<geometry>
				<cylinder length="2.8219324425915286" radius="0.2802727606231159"/>
			</geometry>
		</collision>
		<inertial>
			<mass value="0.6963992066119021"/>
			<inertia ixx="0.03" iyy="0.03" izz="0.03" ixy="0" ixz="0" iyx="0"/>
		</inertial>
	</link>
	<link name="11">
		<visual>
			<geometry>
				<cylinder length="0.7779779338343169" radius="0.2800838665749692"/>
			</geometry>
		</visual>
		<collision>
			<geometry>
				<cylinder length="0.7779779338343169" radius="0.2800838665749692"/>
			</geometry>
		</collision>
		<inertial>
			<mass value="0.1917314418641661"/>
			<inertia ixx="0.03" iyy="0.03" izz="0.03" ixy="0" ixz="0" iyx="0"/>
		</inertial>
	</link>
	<link name="12">
		<visual>
			<geometry>
				<cylinder length="0.7779779338343169" radius="0.2800838665749692"/>
			</geometry>
		</visual>
		<collision>
			<geometry>
				<cylinder length="0.7779779338343169" radius="0.2800838665749692"/>
			</geometry>
		</collision>
		<inertial>
			<mass value="0.1917314418641661"/>
			<inertia ixx="0.03" iyy="0.03" izz="0.03" ixy="0" ixz="0" iyx="0"/>
		</inertial>
	</link>
	<link name="13">
		<visual>
			<geometry>
				<cylinder length="0.7779779338343169" radius="0.2800838665749692"/>
			</geometry>
		</visual>
		<collision>
			<geometry>
				<cylinder length="0.7779779338343169" radius="0.2800838665749692"/>
			</geometry>
		</collision>
		<inertial>
			<mass value="0.1917314418641661"/>
			<inertia ixx="0.03" iyy="0.03" izz="0.03" ixy="0" ixz="0" iyx="0"/>
		</inertial>
	</link>
	<joint name="11_to_0" type="revolute">
		<parent link="0"/>
		<child link="11"/>
		<axis xyz="0 0 1"/>
		<limit effort="1" upper="-3.1415" lower="3.1415" velocity="1"/>
		<origin rpy="3.865062139656801 4.126236558637366 4.990552674009532" xyz="0.9589496066977918 0.6406472672242728 0.17878468067945896"/>
	</joint>
	<joint name="12_to_0" type="revolute">
		<parent link="0"/>
		<child link="12"/>
		<axis xyz="0 0 1"/>
		<limit effort="1" upper="-3.1415" lower="3.1415" velocity="1"/>
		<origin rpy="5.797593209485202 4.126236558637366 4.990552674009532" xyz="0.9589496066977918 0.6406472672242728 0.17878468067945896"/>
	</joint>
	<joint name="13_to_0" type="revolute">
		<parent link="0"/>
		<child link="13"/>
		<axis xyz="0 0 1"/>
		<limit effort="1" upper="-3.1415" lower="3.1415" velocity="1"/>
		<origin rpy="7.730124279313602 4.126236558637366 4.990552674009532" xyz="0.9589496066977918 0.6406472672242728 0.17878468067945896"/>
	</joint>
</robot>
