<?xml version="1.0"?><robot name="pepe">
	<link name="0">
		<visual>
			<geometry>
				<cylinder length="2.8219324425915286" radius="0.2802727606231159"/>
			</geometry>
		</visual>
		<collision>
			<geometry>
				<cylinder length="2.8219324425915286" radius="0.2802727606231159"/>
			</geometry>
		</collision>
		<inertial>
			<mass value="0.6963992066119021"/>
			<inertia ixx="0.03" iyy="0.03" izz="0.03" ixy="0" ixz="0" iyx="0"/>
		</inertial>
	</link>
	<link name="11">
		<visual>
			<geometry>
				<cylinder length="2.0599036324611886" radius="0.077097761671295"/>
			</geometry>
		</visual>
		<collision>
			<geometry>
				<cylinder length="2.0599036324611886" radius="0.077097761671295"/>
			</geometry>
		</collision>
		<inertial>
			<mass value="0.03846629123784332"/>
			<inertia ixx="0.03" iyy="0.03" izz="0.03" ixy="0" ixz="0" iyx="0"/>
		</inertial>
	</link>
	<joint name="11_to_0" type="revolute">
		<parent link="0"/>
		<child link="11"/>
		<axis xyz="0 1 0"/>
		<limit effort="1" upper="-3.1415" lower="3.1415" velocity="1"/>
		<origin rpy="3.4300187434820724 0.2853082720964179 3.064122128781616" xyz="0.07896930179295569 0.4997641074958179 0.33133635138239204"/>
	</joint>
</robot>
