<?xml version="1.0"?><robot name="pepe">
	<link name="0">
		<visual>
			<geometry>
				<cylinder length="1.3303240535078822" radius="0.3058566576238244"/>
			</geometry>
		</visual>
		<collision>
			<geometry>
				<cylinder length="1.3303240535078822" radius="0.3058566576238244"/>
			</geometry>
		</collision>
		<inertial>
			<mass value="0.3909697826612453"/>
			<inertia ixx="0.03" iyy="0.03" izz="0.03" ixy="0" ixz="0" iyx="0"/>
		</inertial>
	</link>
	<link name="11">
		<visual>
			<geometry>
				<cylinder length="1.3303240535078822" radius="0.3058566576238244"/>
			</geometry>
		</visual>
		<collision>
			<geometry>
				<cylinder length="1.3303240535078822" radius="0.3058566576238244"/>
			</geometry>
		</collision>
		<inertial>
			<mass value="0.3909697826612453"/>
			<inertia ixx="0.03" iyy="0.03" izz="0.03" ixy="0" ixz="0" iyx="0"/>
		</inertial>
	</link>
	<joint name="11_to_0" type="revolute">
		<parent link="0"/>
		<child link="11"/>
		<axis xyz="0 0 1"/>
		<limit effort="1" upper="-3.1415" lower="3.1415" velocity="1"/>
		<origin rpy="8.536785572425709 0.9448525096597806 4.765633121334139" xyz="0.08307069296480707 0.507141818168463 0.5397585539410605"/>
	</joint>
</robot>
