<?xml version="1.0"?><robot name="pepe">
	<link name="0">
		<visual>
			<geometry>
				<cylinder length="2.6780468539074365" radius="0.9999"/>
			</geometry>
		</visual>
		<collision>
			<geometry>
				<cylinder length="2.6780468539074365" radius="0.9999"/>
			</geometry>
		</collision>
		<inertial>
			<mass value="8.411649739873743"/>
			<inertia ixx="0.03" iyy="0.03" izz="0.03" ixy="0" ixz="0" iyx="0"/>
		</inertial>
	</link>
	<link name="11">
		<visual>
			<geometry>
				<cylinder length="2.6780468539074365" radius="0.9999"/>
			</geometry>
		</visual>
		<collision>
			<geometry>
				<cylinder length="2.6780468539074365" radius="0.9999"/>
			</geometry>
		</collision>
		<inertial>
			<mass value="8.411649739873743"/>
			<inertia ixx="0.03" iyy="0.03" izz="0.03" ixy="0" ixz="0" iyx="0"/>
		</inertial>
	</link>
	<link name="22">
		<visual>
			<geometry>
				<cylinder length="0.5150071012522092" radius="0.7763839791063876"/>
			</geometry>
		</visual>
		<collision>
			<geometry>
				<cylinder length="0.5150071012522092" radius="0.7763839791063876"/>
			</geometry>
		</collision>
		<inertial>
			<mass value="0.9752505864963112"/>
			<inertia ixx="0.03" iyy="0.03" izz="0.03" ixy="0" ixz="0" iyx="0"/>
		</inertial>
	</link>
	<link name="23">
		<visual>
			<geometry>
				<cylinder length="0.5150071012522092" radius="0.7763839791063876"/>
			</geometry>
		</visual>
		<collision>
			<geometry>
				<cylinder length="0.5150071012522092" radius="0.7763839791063876"/>
			</geometry>
		</collision>
		<inertial>
			<mass value="0.9752505864963112"/>
			<inertia ixx="0.03" iyy="0.03" izz="0.03" ixy="0" ixz="0" iyx="0"/>
		</inertial>
	</link>
	<link name="24">
		<visual>
			<geometry>
				<cylinder length="0.5150071012522092" radius="0.7763839791063876"/>
			</geometry>
		</visual>
		<collision>
			<geometry>
				<cylinder length="0.5150071012522092" radius="0.7763839791063876"/>
			</geometry>
		</collision>
		<inertial>
			<mass value="0.9752505864963112"/>
			<inertia ixx="0.03" iyy="0.03" izz="0.03" ixy="0" ixz="0" iyx="0"/>
		</inertial>
	</link>
	<joint name="11_to_0" type="revolute">
		<parent link="0"/>
		<child link="11"/>
		<axis xyz="0 1 0"/>
		<limit effort="1" upper="-3.1415" lower="3.1415" velocity="1"/>
		<origin rpy="0.7978502867217495 6.225550231962962 1.5650392050855029" xyz="0.1319503410670193 0.058181755163629334 0.8637086315317808"/>
	</joint>
	<joint name="22_to_0" type="spherical">
		<parent link="0"/>
		<child link="22"/>
		<axis xyz="0 0 1"/>
		<limit effort="1" upper="-3.1415" lower="3.1415" velocity="1"/>
		<origin rpy="1.07439614792092 4.92619088350301 1.3273264372557645" xyz="0.04812822035635622 0.3691826595748132 0.06594306544400708"/>
	</joint>
	<joint name="23_to_0" type="spherical">
		<parent link="0"/>
		<child link="23"/>
		<axis xyz="0 0 1"/>
		<limit effort="1" upper="-3.1415" lower="3.1415" velocity="1"/>
		<origin rpy="1.4325281972278936 4.92619088350301 1.3273264372557645" xyz="0.04812822035635622 0.3691826595748132 0.06594306544400708"/>
	</joint>
	<joint name="24_to_0" type="spherical">
		<parent link="0"/>
		<child link="24"/>
		<axis xyz="0 0 1"/>
		<limit effort="1" upper="-3.1415" lower="3.1415" velocity="1"/>
		<origin rpy="1.790660246534867 4.92619088350301 1.3273264372557645" xyz="0.04812822035635622 0.3691826595748132 0.06594306544400708"/>
	</joint>
</robot>
