<?xml version="1.0"?><robot name="pepe">
	<link name="0">
		<visual>
			<geometry>
				<cylinder length="3.489037125475815" radius="0.45186644183614755"/>
			</geometry>
		</visual>
		<collision>
			<geometry>
				<cylinder length="3.489037125475815" radius="0.45186644183614755"/>
			</geometry>
		</collision>
		<inertial>
			<mass value="2.238080184220572"/>
			<inertia ixx="0.03" iyy="0.03" izz="0.03" ixy="0" ixz="0" iyx="0"/>
		</inertial>
	</link>
	<link name="11">
		<visual>
			<geometry>
				<cylinder length="3.7894306942223532" radius="0.429426581632902"/>
			</geometry>
		</visual>
		<collision>
			<geometry>
				<cylinder length="3.7894306942223532" radius="0.429426581632902"/>
			</geometry>
		</collision>
		<inertial>
			<mass value="2.195339487122738"/>
			<inertia ixx="0.03" iyy="0.03" izz="0.03" ixy="0" ixz="0" iyx="0"/>
		</inertial>
	</link>
	<link name="12">
		<visual>
			<geometry>
				<cylinder length="3.7894306942223532" radius="0.429426581632902"/>
			</geometry>
		</visual>
		<collision>
			<geometry>
				<cylinder length="3.7894306942223532" radius="0.429426581632902"/>
			</geometry>
		</collision>
		<inertial>
			<mass value="2.195339487122738"/>
			<inertia ixx="0.03" iyy="0.03" izz="0.03" ixy="0" ixz="0" iyx="0"/>
		</inertial>
	</link>
	<link name="13">
		<visual>
			<geometry>
				<cylinder length="3.7894306942223532" radius="0.429426581632902"/>
			</geometry>
		</visual>
		<collision>
			<geometry>
				<cylinder length="3.7894306942223532" radius="0.429426581632902"/>
			</geometry>
		</collision>
		<inertial>
			<mass value="2.195339487122738"/>
			<inertia ixx="0.03" iyy="0.03" izz="0.03" ixy="0" ixz="0" iyx="0"/>
		</inertial>
	</link>
	<joint name="11_to_0" type="revolute">
		<parent link="0"/>
		<child link="11"/>
		<axis xyz="0 0 1"/>
		<limit effort="1" upper="-3.1415" lower="3.1415" velocity="1"/>
		<origin rpy="7.963595741671975 1.207146680189356 0.8719670623217749" xyz="0.3938877761883527 0.04531971979903282 0.17895795268787817"/>
	</joint>
	<joint name="12_to_0" type="revolute">
		<parent link="0"/>
		<child link="12"/>
		<axis xyz="0 0 1"/>
		<limit effort="1" upper="-3.1415" lower="3.1415" velocity="1"/>
		<origin rpy="11.945393612507964 1.207146680189356 0.8719670623217749" xyz="0.3938877761883527 0.04531971979903282 0.17895795268787817"/>
	</joint>
	<joint name="13_to_0" type="revolute">
		<parent link="0"/>
		<child link="13"/>
		<axis xyz="0 0 1"/>
		<limit effort="1" upper="-3.1415" lower="3.1415" velocity="1"/>
		<origin rpy="15.92719148334395 1.207146680189356 0.8719670623217749" xyz="0.3938877761883527 0.04531971979903282 0.17895795268787817"/>
	</joint>
</robot>
