<?xml version="1.0"?><robot name="pepe">
	<link name="0">
		<visual>
			<geometry>
				<cylinder length="0.7893298455281619" radius="0.4449545980872709"/>
			</geometry>
		</visual>
		<collision>
			<geometry>
				<cylinder length="0.7893298455281619" radius="0.4449545980872709"/>
			</geometry>
		</collision>
		<inertial>
			<mass value="0.4909528609240759"/>
			<inertia ixx="0.03" iyy="0.03" izz="0.03" ixy="0" ixz="0" iyx="0"/>
		</inertial>
	</link>
	<link name="11">
		<visual>
			<geometry>
				<cylinder length="0.7893298455281619" radius="0.4449545980872709"/>
			</geometry>
		</visual>
		<collision>
			<geometry>
				<cylinder length="0.7893298455281619" radius="0.4449545980872709"/>
			</geometry>
		</collision>
		<inertial>
			<mass value="0.4909528609240759"/>
			<inertia ixx="0.03" iyy="0.03" izz="0.03" ixy="0" ixz="0" iyx="0"/>
		</inertial>
	</link>
	<link name="12">
		<visual>
			<geometry>
				<cylinder length="0.7893298455281619" radius="0.4449545980872709"/>
			</geometry>
		</visual>
		<collision>
			<geometry>
				<cylinder length="0.7893298455281619" radius="0.4449545980872709"/>
			</geometry>
		</collision>
		<inertial>
			<mass value="0.4909528609240759"/>
			<inertia ixx="0.03" iyy="0.03" izz="0.03" ixy="0" ixz="0" iyx="0"/>
		</inertial>
	</link>
	<joint name="11_to_0" type="revolute">
		<parent link="0"/>
		<child link="11"/>
		<axis xyz="1 0 0"/>
		<limit effort="1" upper="-3.1415" lower="3.1415" velocity="1"/>
		<origin rpy="11.09397827292539 0.26524334692476825 2.146461179100148" xyz="0.7222440661276474 0.9707286802902778 0.9473751457952274"/>
	</joint>
	<joint name="12_to_0" type="revolute">
		<parent link="0"/>
		<child link="12"/>
		<axis xyz="1 0 0"/>
		<limit effort="1" upper="-3.1415" lower="3.1415" velocity="1"/>
		<origin rpy="16.640967409388086 0.26524334692476825 2.146461179100148" xyz="0.7222440661276474 0.9707286802902778 0.9473751457952274"/>
	</joint>
</robot>
