<?xml version="1.0"?><robot name="pepe">
	<link name="0">
		<visual>
			<geometry>
				<cylinder length="2.8219324425915286" radius="0.2802727606231159"/>
			</geometry>
		</visual>
		<collision>
			<geometry>
				<cylinder length="2.8219324425915286" radius="0.2802727606231159"/>
			</geometry>
		</collision>
		<inertial>
			<mass value="0.6963992066119021"/>
			<inertia ixx="0.03" iyy="0.03" izz="0.03" ixy="0" ixz="0" iyx="0"/>
		</inertial>
	</link>
	<link name="11">
		<visual>
			<geometry>
				<cylinder length="1.9350161549564626" radius="0.03975856454027582"/>
			</geometry>
		</visual>
		<collision>
			<geometry>
				<cylinder length="1.9350161549564626" radius="0.03975856454027582"/>
			</geometry>
		</collision>
		<inertial>
			<mass value="0.009609390891341682"/>
			<inertia ixx="0.03" iyy="0.03" izz="0.03" ixy="0" ixz="0" iyx="0"/>
		</inertial>
	</link>
	<link name="12">
		<visual>
			<geometry>
				<cylinder length="1.9350161549564626" radius="0.03975856454027582"/>
			</geometry>
		</visual>
		<collision>
			<geometry>
				<cylinder length="1.9350161549564626" radius="0.03975856454027582"/>
			</geometry>
		</collision>
		<inertial>
			<mass value="0.009609390891341682"/>
			<inertia ixx="0.03" iyy="0.03" izz="0.03" ixy="0" ixz="0" iyx="0"/>
		</inertial>
	</link>
	<joint name="11_to_0" type="revolute">
		<parent link="0"/>
		<child link="11"/>
		<axis xyz="1 0 0"/>
		<limit effort="1" upper="-3.1415" lower="3.1415" velocity="1"/>
		<origin rpy="0.3500619068412015 1.9306671821626888 2.935201553877297" xyz="0.9080515190631776 0.8739489838468218 0.17539322293207127"/>
	</joint>
	<joint name="12_to_0" type="revolute">
		<parent link="0"/>
		<child link="12"/>
		<axis xyz="1 0 0"/>
		<limit effort="1" upper="-3.1415" lower="3.1415" velocity="1"/>
		<origin rpy="0.5250928602618022 1.9306671821626888 2.935201553877297" xyz="0.9080515190631776 0.8739489838468218 0.17539322293207127"/>
	</joint>
</robot>
