<?xml version="1.0"?><robot name="pepe">
	<link name="0">
		<visual>
			<geometry>
				<cylinder length="2.052335271366942" radius="0.9127046226389154"/>
			</geometry>
		</visual>
		<collision>
			<geometry>
				<cylinder length="2.052335271366942" radius="0.9127046226389154"/>
			</geometry>
		</collision>
		<inertial>
			<mass value="5.371043651051132"/>
			<inertia ixx="0.03" iyy="0.03" izz="0.03" ixy="0" ixz="0" iyx="0"/>
		</inertial>
	</link>
	<link name="11">
		<visual>
			<geometry>
				<cylinder length="1.209598240886392" radius="0.4682555543574971"/>
			</geometry>
		</visual>
		<collision>
			<geometry>
				<cylinder length="1.209598240886392" radius="0.4682555543574971"/>
			</geometry>
		</collision>
		<inertial>
			<mass value="0.8332146444802512"/>
			<inertia ixx="0.03" iyy="0.03" izz="0.03" ixy="0" ixz="0" iyx="0"/>
		</inertial>
	</link>
	<link name="12">
		<visual>
			<geometry>
				<cylinder length="1.209598240886392" radius="0.4682555543574971"/>
			</geometry>
		</visual>
		<collision>
			<geometry>
				<cylinder length="1.209598240886392" radius="0.4682555543574971"/>
			</geometry>
		</collision>
		<inertial>
			<mass value="0.8332146444802512"/>
			<inertia ixx="0.03" iyy="0.03" izz="0.03" ixy="0" ixz="0" iyx="0"/>
		</inertial>
	</link>
	<joint name="11_to_0" type="revolute">
		<parent link="0"/>
		<child link="11"/>
		<axis xyz="1 0 0"/>
		<limit effort="1" upper="-3.1415" lower="3.1415" velocity="1"/>
		<origin rpy="8.855594217367054 3.6816516015654828 0.9553175657347027" xyz="0.7203587746564706 0.6726142639003868 0.9464490950621813"/>
	</joint>
	<joint name="12_to_0" type="revolute">
		<parent link="0"/>
		<child link="12"/>
		<axis xyz="1 0 0"/>
		<limit effort="1" upper="-3.1415" lower="3.1415" velocity="1"/>
		<origin rpy="13.28339132605058 3.6816516015654828 0.9553175657347027" xyz="0.7203587746564706 0.6726142639003868 0.9464490950621813"/>
	</joint>
</robot>
