<?xml version="1.0"?><robot name="pepe">
	<link name="0">
		<visual>
			<geometry>
				<cylinder length="2.9780468539074367" radius="0.9999"/>
			</geometry>
		</visual>
		<collision>
			<geometry>
				<cylinder length="2.9780468539074367" radius="0.9999"/>
			</geometry>
		</collision>
		<inertial>
			<mass value="9.353939049816244"/>
			<inertia ixx="0.03" iyy="0.03" izz="0.03" ixy="0" ixz="0" iyx="0"/>
		</inertial>
	</link>
	<link name="11">
		<visual>
			<geometry>
				<cylinder length="1.234312719216514" radius="0.0007693908955036521"/>
			</geometry>
		</visual>
		<collision>
			<geometry>
				<cylinder length="1.234312719216514" radius="0.0007693908955036521"/>
			</geometry>
		</collision>
		<inertial>
			<mass value="2.2954570050142506e-06"/>
			<inertia ixx="0.03" iyy="0.03" izz="0.03" ixy="0" ixz="0" iyx="0"/>
		</inertial>
	</link>
	<link name="12">
		<visual>
			<geometry>
				<cylinder length="1.234312719216514" radius="0.0007693908955036521"/>
			</geometry>
		</visual>
		<collision>
			<geometry>
				<cylinder length="1.234312719216514" radius="0.0007693908955036521"/>
			</geometry>
		</collision>
		<inertial>
			<mass value="2.2954570050142506e-06"/>
			<inertia ixx="0.03" iyy="0.03" izz="0.03" ixy="0" ixz="0" iyx="0"/>
		</inertial>
	</link>
	<link name="13">
		<visual>
			<geometry>
				<cylinder length="1.234312719216514" radius="0.0007693908955036521"/>
			</geometry>
		</visual>
		<collision>
			<geometry>
				<cylinder length="1.234312719216514" radius="0.0007693908955036521"/>
			</geometry>
		</collision>
		<inertial>
			<mass value="2.2954570050142506e-06"/>
			<inertia ixx="0.03" iyy="0.03" izz="0.03" ixy="0" ixz="0" iyx="0"/>
		</inertial>
	</link>
	<joint name="11_to_0" type="revolute">
		<parent link="0"/>
		<child link="11"/>
		<axis xyz="1 0 0"/>
		<limit effort="1" upper="-3.1415" lower="3.1415" velocity="1"/>
		<origin rpy="4.588479504368967 2.13672479556915 0.7684987398499307" xyz="0.628354619428031 0.3326012679928375 0.2654775550477634"/>
	</joint>
	<joint name="12_to_0" type="revolute">
		<parent link="0"/>
		<child link="12"/>
		<axis xyz="1 0 0"/>
		<limit effort="1" upper="-3.1415" lower="3.1415" velocity="1"/>
		<origin rpy="6.88271925655345 2.13672479556915 0.7684987398499307" xyz="0.628354619428031 0.3326012679928375 0.2654775550477634"/>
	</joint>
	<joint name="13_to_0" type="revolute">
		<parent link="0"/>
		<child link="13"/>
		<axis xyz="1 0 0"/>
		<limit effort="1" upper="-3.1415" lower="3.1415" velocity="1"/>
		<origin rpy="9.176959008737933 2.13672479556915 0.7684987398499307" xyz="0.628354619428031 0.3326012679928375 0.2654775550477634"/>
	</joint>
</robot>
