<?xml version="1.0"?><robot name="pepe">
	<link name="0">
		<visual>
			<geometry>
				<cylinder length="2.9780468539074367" radius="0.9999"/>
			</geometry>
		</visual>
		<collision>
			<geometry>
				<cylinder length="2.9780468539074367" radius="0.9999"/>
			</geometry>
		</collision>
		<inertial>
			<mass value="9.353939049816244"/>
			<inertia ixx="0.03" iyy="0.03" izz="0.03" ixy="0" ixz="0" iyx="0"/>
		</inertial>
	</link>
	<link name="11">
		<visual>
			<geometry>
				<cylinder length="2.6780468539074365" radius="0.9999"/>
			</geometry>
		</visual>
		<collision>
			<geometry>
				<cylinder length="2.6780468539074365" radius="0.9999"/>
			</geometry>
		</collision>
		<inertial>
			<mass value="8.411649739873743"/>
			<inertia ixx="0.03" iyy="0.03" izz="0.03" ixy="0" ixz="0" iyx="0"/>
		</inertial>
	</link>
	<joint name="11_to_0" type="revolute">
		<parent link="0"/>
		<child link="11"/>
		<axis xyz="0 1 0"/>
		<limit effort="1" upper="-3.1415" lower="3.1415" velocity="1"/>
		<origin rpy="0.7978502867217495 6.225550231962962 1.5650392050855029" xyz="0.1319503410670193 0.058181755163629334 0.8637086315317808"/>
	</joint>
</robot>
