<?xml version="1.0"?><robot name="pepe">
	<link name="0">
		<visual>
			<geometry>
				<cylinder length="2.9780468539074367" radius="0.9999"/>
			</geometry>
		</visual>
		<collision>
			<geometry>
				<cylinder length="2.9780468539074367" radius="0.9999"/>
			</geometry>
		</collision>
		<inertial>
			<mass value="9.353939049816244"/>
			<inertia ixx="0.03" iyy="0.03" izz="0.03" ixy="0" ixz="0" iyx="0"/>
		</inertial>
	</link>
	<link name="11">
		<visual>
			<geometry>
				<cylinder length="2.828600339542634" radius="0.6938138397679887"/>
			</geometry>
		</visual>
		<collision>
			<geometry>
				<cylinder length="2.828600339542634" radius="0.6938138397679887"/>
			</geometry>
		</collision>
		<inertial>
			<mass value="4.277670996362868"/>
			<inertia ixx="0.03" iyy="0.03" izz="0.03" ixy="0" ixz="0" iyx="0"/>
		</inertial>
	</link>
	<link name="12">
		<visual>
			<geometry>
				<cylinder length="2.828600339542634" radius="0.6938138397679887"/>
			</geometry>
		</visual>
		<collision>
			<geometry>
				<cylinder length="2.828600339542634" radius="0.6938138397679887"/>
			</geometry>
		</collision>
		<inertial>
			<mass value="4.277670996362868"/>
			<inertia ixx="0.03" iyy="0.03" izz="0.03" ixy="0" ixz="0" iyx="0"/>
		</inertial>
	</link>
	<joint name="11_to_0" type="revolute">
		<parent link="0"/>
		<child link="11"/>
		<axis xyz="1 0 0"/>
		<limit effort="1" upper="-3.1415" lower="3.1415" velocity="1"/>
		<origin rpy="10.632262881715466 4.692167601130776 5.966355161653299" xyz="0.6720814643060062 0.8599947634534268 0.9529843849685246"/>
	</joint>
	<joint name="12_to_0" type="revolute">
		<parent link="0"/>
		<child link="12"/>
		<axis xyz="1 0 0"/>
		<limit effort="1" upper="-3.1415" lower="3.1415" velocity="1"/>
		<origin rpy="15.948394322573199 4.692167601130776 5.966355161653299" xyz="0.6720814643060062 0.8599947634534268 0.9529843849685246"/>
	</joint>
</robot>
