<?xml version="1.0"?><robot name="pepe">
	<link name="0">
		<visual>
			<geometry>
				<cylinder length="2.6780468539074365" radius="0.9999"/>
			</geometry>
		</visual>
		<collision>
			<geometry>
				<cylinder length="2.6780468539074365" radius="0.9999"/>
			</geometry>
		</collision>
		<inertial>
			<mass value="8.411649739873743"/>
			<inertia ixx="0.03" iyy="0.03" izz="0.03" ixy="0" ixz="0" iyx="0"/>
		</inertial>
	</link>
	<link name="11">
		<visual>
			<geometry>
				<cylinder length="2.6780468539074365" radius="0.9999"/>
			</geometry>
		</visual>
		<collision>
			<geometry>
				<cylinder length="2.6780468539074365" radius="0.9999"/>
			</geometry>
		</collision>
		<inertial>
			<mass value="8.411649739873743"/>
			<inertia ixx="0.03" iyy="0.03" izz="0.03" ixy="0" ixz="0" iyx="0"/>
		</inertial>
	</link>
	<link name="22">
		<visual>
			<geometry>
				<cylinder length="1.6351083183453388" radius="0.31446553857254866"/>
			</geometry>
		</visual>
		<collision>
			<geometry>
				<cylinder length="1.6351083183453388" radius="0.31446553857254866"/>
			</geometry>
		</collision>
		<inertial>
			<mass value="0.5079752106607446"/>
			<inertia ixx="0.03" iyy="0.03" izz="0.03" ixy="0" ixz="0" iyx="0"/>
		</inertial>
	</link>
	<link name="23">
		<visual>
			<geometry>
				<cylinder length="1.6351083183453388" radius="0.31446553857254866"/>
			</geometry>
		</visual>
		<collision>
			<geometry>
				<cylinder length="1.6351083183453388" radius="0.31446553857254866"/>
			</geometry>
		</collision>
		<inertial>
			<mass value="0.5079752106607446"/>
			<inertia ixx="0.03" iyy="0.03" izz="0.03" ixy="0" ixz="0" iyx="0"/>
		</inertial>
	</link>
	<link name="24">
		<visual>
			<geometry>
				<cylinder length="1.6351083183453388" radius="0.31446553857254866"/>
			</geometry>
		</visual>
		<collision>
			<geometry>
				<cylinder length="1.6351083183453388" radius="0.31446553857254866"/>
			</geometry>
		</collision>
		<inertial>
			<mass value="0.5079752106607446"/>
			<inertia ixx="0.03" iyy="0.03" izz="0.03" ixy="0" ixz="0" iyx="0"/>
		</inertial>
	</link>
	<joint name="11_to_0" type="revolute">
		<parent link="0"/>
		<child link="11"/>
		<axis xyz="0 1 0"/>
		<limit effort="1" upper="-3.1415" lower="3.1415" velocity="1"/>
		<origin rpy="0.7978502867217495 6.225550231962962 1.5650392050855029" xyz="0.1319503410670193 0.058181755163629334 0.8637086315317808"/>
	</joint>
	<joint name="22_to_0" type="revolute">
		<parent link="0"/>
		<child link="22"/>
		<axis xyz="0 1 0"/>
		<limit effort="1" upper="-3.1415" lower="3.1415" velocity="1"/>
		<origin rpy="4.621213582341783 0.5325209087107884 0.1620270720668011" xyz="0.32127426036859785 0.500835277804333 0.4726795650979667"/>
	</joint>
	<joint name="23_to_0" type="revolute">
		<parent link="0"/>
		<child link="23"/>
		<axis xyz="0 1 0"/>
		<limit effort="1" upper="-3.1415" lower="3.1415" velocity="1"/>
		<origin rpy="6.161618109789044 0.5325209087107884 0.1620270720668011" xyz="0.32127426036859785 0.500835277804333 0.4726795650979667"/>
	</joint>
	<joint name="24_to_0" type="revolute">
		<parent link="0"/>
		<child link="24"/>
		<axis xyz="0 1 0"/>
		<limit effort="1" upper="-3.1415" lower="3.1415" velocity="1"/>
		<origin rpy="7.702022637236306 0.5325209087107884 0.1620270720668011" xyz="0.32127426036859785 0.500835277804333 0.4726795650979667"/>
	</joint>
</robot>
