<?xml version="1.0"?><robot name="pepe">
	<link name="0">
		<visual>
			<geometry>
				<cylinder length="2.9780468539074367" radius="0.9999"/>
			</geometry>
		</visual>
		<collision>
			<geometry>
				<cylinder length="2.9780468539074367" radius="0.9999"/>
			</geometry>
		</collision>
		<inertial>
			<mass value="9.353939049816244"/>
			<inertia ixx="0.03" iyy="0.03" izz="0.03" ixy="0" ixz="0" iyx="0"/>
		</inertial>
	</link>
	<link name="11">
		<visual>
			<geometry>
				<cylinder length="0.582590645104403" radius="0.6946852157038984"/>
			</geometry>
		</visual>
		<collision>
			<geometry>
				<cylinder length="0.582590645104403" radius="0.6946852157038984"/>
			</geometry>
		</collision>
		<inertial>
			<mass value="0.8832618892675721"/>
			<inertia ixx="0.03" iyy="0.03" izz="0.03" ixy="0" ixz="0" iyx="0"/>
		</inertial>
	</link>
	<link name="12">
		<visual>
			<geometry>
				<cylinder length="0.582590645104403" radius="0.6946852157038984"/>
			</geometry>
		</visual>
		<collision>
			<geometry>
				<cylinder length="0.582590645104403" radius="0.6946852157038984"/>
			</geometry>
		</collision>
		<inertial>
			<mass value="0.8832618892675721"/>
			<inertia ixx="0.03" iyy="0.03" izz="0.03" ixy="0" ixz="0" iyx="0"/>
		</inertial>
	</link>
	<link name="13">
		<visual>
			<geometry>
				<cylinder length="0.582590645104403" radius="0.6946852157038984"/>
			</geometry>
		</visual>
		<collision>
			<geometry>
				<cylinder length="0.582590645104403" radius="0.6946852157038984"/>
			</geometry>
		</collision>
		<inertial>
			<mass value="0.8832618892675721"/>
			<inertia ixx="0.03" iyy="0.03" izz="0.03" ixy="0" ixz="0" iyx="0"/>
		</inertial>
	</link>
	<joint name="11_to_0" type="revolute">
		<parent link="0"/>
		<child link="11"/>
		<axis xyz="0 1 0"/>
		<limit effort="1" upper="-3.1415" lower="3.1415" velocity="1"/>
		<origin rpy="11.930943478905922 0.7320380403022715 3.0690841649174585" xyz="0.012173695424175568 0.8040828675276419 0.9258188655549258"/>
	</joint>
	<joint name="12_to_0" type="revolute">
		<parent link="0"/>
		<child link="12"/>
		<axis xyz="0 1 0"/>
		<limit effort="1" upper="-3.1415" lower="3.1415" velocity="1"/>
		<origin rpy="17.896415218358882 0.7320380403022715 3.0690841649174585" xyz="0.012173695424175568 0.8040828675276419 0.9258188655549258"/>
	</joint>
	<joint name="13_to_0" type="revolute">
		<parent link="0"/>
		<child link="13"/>
		<axis xyz="0 1 0"/>
		<limit effort="1" upper="-3.1415" lower="3.1415" velocity="1"/>
		<origin rpy="23.861886957811844 0.7320380403022715 3.0690841649174585" xyz="0.012173695424175568 0.8040828675276419 0.9258188655549258"/>
	</joint>
</robot>
