<?xml version="1.0"?><robot name="pepe">
	<link name="0">
		<visual>
			<geometry>
				<cylinder length="0.014274410217682942" radius="0.8156512871800198"/>
			</geometry>
		</visual>
		<collision>
			<geometry>
				<cylinder length="0.014274410217682942" radius="0.8156512871800198"/>
			</geometry>
		</collision>
		<inertial>
			<mass value="0.02983438554911769"/>
			<inertia ixx="0.03" iyy="0.03" izz="0.03" ixy="0" ixz="0" iyx="0"/>
		</inertial>
	</link>
	<link name="11">
		<visual>
			<geometry>
				<cylinder length="0.2899771174313228" radius="0.9913186250259912"/>
			</geometry>
		</visual>
		<collision>
			<geometry>
				<cylinder length="0.2899771174313228" radius="0.9913186250259912"/>
			</geometry>
		</collision>
		<inertial>
			<mass value="0.8952413484899503"/>
			<inertia ixx="0.03" iyy="0.03" izz="0.03" ixy="0" ixz="0" iyx="0"/>
		</inertial>
	</link>
	<link name="12">
		<visual>
			<geometry>
				<cylinder length="0.2899771174313228" radius="0.9913186250259912"/>
			</geometry>
		</visual>
		<collision>
			<geometry>
				<cylinder length="0.2899771174313228" radius="0.9913186250259912"/>
			</geometry>
		</collision>
		<inertial>
			<mass value="0.8952413484899503"/>
			<inertia ixx="0.03" iyy="0.03" izz="0.03" ixy="0" ixz="0" iyx="0"/>
		</inertial>
	</link>
	<link name="13">
		<visual>
			<geometry>
				<cylinder length="0.2899771174313228" radius="0.9913186250259912"/>
			</geometry>
		</visual>
		<collision>
			<geometry>
				<cylinder length="0.2899771174313228" radius="0.9913186250259912"/>
			</geometry>
		</collision>
		<inertial>
			<mass value="0.8952413484899503"/>
			<inertia ixx="0.03" iyy="0.03" izz="0.03" ixy="0" ixz="0" iyx="0"/>
		</inertial>
	</link>
	<link name="24">
		<visual>
			<geometry>
				<cylinder length="2.8042276160564343" radius="0.5407293334418316"/>
			</geometry>
		</visual>
		<collision>
			<geometry>
				<cylinder length="2.8042276160564343" radius="0.5407293334418316"/>
			</geometry>
		</collision>
		<inertial>
			<mass value="2.5758643837753263"/>
			<inertia ixx="0.03" iyy="0.03" izz="0.03" ixy="0" ixz="0" iyx="0"/>
		</inertial>
	</link>
	<link name="35">
		<visual>
			<geometry>
				<cylinder length="0.6034960358226125" radius="0.9674104953397925"/>
			</geometry>
		</visual>
		<collision>
			<geometry>
				<cylinder length="0.6034960358226125" radius="0.9674104953397925"/>
			</geometry>
		</collision>
		<inertial>
			<mass value="1.7743769362421675"/>
			<inertia ixx="0.03" iyy="0.03" izz="0.03" ixy="0" ixz="0" iyx="0"/>
		</inertial>
	</link>
	<link name="46">
		<visual>
			<geometry>
				<cylinder length="2.1814484607108575" radius="0.16507204536310838"/>
			</geometry>
		</visual>
		<collision>
			<geometry>
				<cylinder length="2.1814484607108575" radius="0.16507204536310838"/>
			</geometry>
		</collision>
		<inertial>
			<mass value="0.18674195215773062"/>
			<inertia ixx="0.03" iyy="0.03" izz="0.03" ixy="0" ixz="0" iyx="0"/>
		</inertial>
	</link>
	<link name="47">
		<visual>
			<geometry>
				<cylinder length="2.1814484607108575" radius="0.16507204536310838"/>
			</geometry>
		</visual>
		<collision>
			<geometry>
				<cylinder length="2.1814484607108575" radius="0.16507204536310838"/>
			</geometry>
		</collision>
		<inertial>
			<mass value="0.18674195215773062"/>
			<inertia ixx="0.03" iyy="0.03" izz="0.03" ixy="0" ixz="0" iyx="0"/>
		</inertial>
	</link>
	<link name="38">
		<visual>
			<geometry>
				<cylinder length="0.6034960358226125" radius="0.9674104953397925"/>
			</geometry>
		</visual>
		<collision>
			<geometry>
				<cylinder length="0.6034960358226125" radius="0.9674104953397925"/>
			</geometry>
		</collision>
		<inertial>
			<mass value="1.7743769362421675"/>
			<inertia ixx="0.03" iyy="0.03" izz="0.03" ixy="0" ixz="0" iyx="0"/>
		</inertial>
	</link>
	<link name="49">
		<visual>
			<geometry>
				<cylinder length="2.1814484607108575" radius="0.16507204536310838"/>
			</geometry>
		</visual>
		<collision>
			<geometry>
				<cylinder length="2.1814484607108575" radius="0.16507204536310838"/>
			</geometry>
		</collision>
		<inertial>
			<mass value="0.18674195215773062"/>
			<inertia ixx="0.03" iyy="0.03" izz="0.03" ixy="0" ixz="0" iyx="0"/>
		</inertial>
	</link>
	<link name="410">
		<visual>
			<geometry>
				<cylinder length="2.1814484607108575" radius="0.16507204536310838"/>
			</geometry>
		</visual>
		<collision>
			<geometry>
				<cylinder length="2.1814484607108575" radius="0.16507204536310838"/>
			</geometry>
		</collision>
		<inertial>
			<mass value="0.18674195215773062"/>
			<inertia ixx="0.03" iyy="0.03" izz="0.03" ixy="0" ixz="0" iyx="0"/>
		</inertial>
	</link>
	<link name="211">
		<visual>
			<geometry>
				<cylinder length="2.8042276160564343" radius="0.5407293334418316"/>
			</geometry>
		</visual>
		<collision>
			<geometry>
				<cylinder length="2.8042276160564343" radius="0.5407293334418316"/>
			</geometry>
		</collision>
		<inertial>
			<mass value="2.5758643837753263"/>
			<inertia ixx="0.03" iyy="0.03" izz="0.03" ixy="0" ixz="0" iyx="0"/>
		</inertial>
	</link>
	<link name="312">
		<visual>
			<geometry>
				<cylinder length="0.6034960358226125" radius="0.9674104953397925"/>
			</geometry>
		</visual>
		<collision>
			<geometry>
				<cylinder length="0.6034960358226125" radius="0.9674104953397925"/>
			</geometry>
		</collision>
		<inertial>
			<mass value="1.7743769362421675"/>
			<inertia ixx="0.03" iyy="0.03" izz="0.03" ixy="0" ixz="0" iyx="0"/>
		</inertial>
	</link>
	<link name="413">
		<visual>
			<geometry>
				<cylinder length="2.1814484607108575" radius="0.16507204536310838"/>
			</geometry>
		</visual>
		<collision>
			<geometry>
				<cylinder length="2.1814484607108575" radius="0.16507204536310838"/>
			</geometry>
		</collision>
		<inertial>
			<mass value="0.18674195215773062"/>
			<inertia ixx="0.03" iyy="0.03" izz="0.03" ixy="0" ixz="0" iyx="0"/>
		</inertial>
	</link>
	<link name="414">
		<visual>
			<geometry>
				<cylinder length="2.1814484607108575" radius="0.16507204536310838"/>
			</geometry>
		</visual>
		<collision>
			<geometry>
				<cylinder length="2.1814484607108575" radius="0.16507204536310838"/>
			</geometry>
		</collision>
		<inertial>
			<mass value="0.18674195215773062"/>
			<inertia ixx="0.03" iyy="0.03" izz="0.03" ixy="0" ixz="0" iyx="0"/>
		</inertial>
	</link>
	<link name="315">
		<visual>
			<geometry>
				<cylinder length="0.6034960358226125" radius="0.9674104953397925"/>
			</geometry>
		</visual>
		<collision>
			<geometry>
				<cylinder length="0.6034960358226125" radius="0.9674104953397925"/>
			</geometry>
		</collision>
		<inertial>
			<mass value="1.7743769362421675"/>
			<inertia ixx="0.03" iyy="0.03" izz="0.03" ixy="0" ixz="0" iyx="0"/>
		</inertial>
	</link>
	<link name="416">
		<visual>
			<geometry>
				<cylinder length="2.1814484607108575" radius="0.16507204536310838"/>
			</geometry>
		</visual>
		<collision>
			<geometry>
				<cylinder length="2.1814484607108575" radius="0.16507204536310838"/>
			</geometry>
		</collision>
		<inertial>
			<mass value="0.18674195215773062"/>
			<inertia ixx="0.03" iyy="0.03" izz="0.03" ixy="0" ixz="0" iyx="0"/>
		</inertial>
	</link>
	<link name="417">
		<visual>
			<geometry>
				<cylinder length="2.1814484607108575" radius="0.16507204536310838"/>
			</geometry>
		</visual>
		<collision>
			<geometry>
				<cylinder length="2.1814484607108575" radius="0.16507204536310838"/>
			</geometry>
		</collision>
		<inertial>
			<mass value="0.18674195215773062"/>
			<inertia ixx="0.03" iyy="0.03" izz="0.03" ixy="0" ixz="0" iyx="0"/>
		</inertial>
	</link>
	<link name="518">
		<visual>
			<geometry>
				<cylinder length="0.2729897140465759" radius="0.9297865949663323"/>
			</geometry>
		</visual>
		<collision>
			<geometry>
				<cylinder length="0.2729897140465759" radius="0.9297865949663323"/>
			</geometry>
		</collision>
		<inertial>
			<mass value="0.7414173031681403"/>
			<inertia ixx="0.03" iyy="0.03" izz="0.03" ixy="0" ixz="0" iyx="0"/>
		</inertial>
	</link>
	<link name="519">
		<visual>
			<geometry>
				<cylinder length="0.2729897140465759" radius="0.9297865949663323"/>
			</geometry>
		</visual>
		<collision>
			<geometry>
				<cylinder length="0.2729897140465759" radius="0.9297865949663323"/>
			</geometry>
		</collision>
		<inertial>
			<mass value="0.7414173031681403"/>
			<inertia ixx="0.03" iyy="0.03" izz="0.03" ixy="0" ixz="0" iyx="0"/>
		</inertial>
	</link>
	<joint name="11_to_0" type="revolute">
		<parent link="0"/>
		<child link="11"/>
		<axis xyz="0 1 0"/>
		<limit effort="1" upper="-3.1415" lower="3.1415" velocity="1"/>
		<origin rpy="3.1279548086478646 3.948159383639452 3.7229714195462145" xyz="0.6558871288496995 0.7560724549748009 0.34690984980424955"/>
	</joint>
	<joint name="12_to_0" type="revolute">
		<parent link="0"/>
		<child link="12"/>
		<axis xyz="0 1 0"/>
		<limit effort="1" upper="-3.1415" lower="3.1415" velocity="1"/>
		<origin rpy="4.691932212971797 3.948159383639452 3.7229714195462145" xyz="0.6558871288496995 0.7560724549748009 0.34690984980424955"/>
	</joint>
	<joint name="13_to_0" type="revolute">
		<parent link="0"/>
		<child link="13"/>
		<axis xyz="0 1 0"/>
		<limit effort="1" upper="-3.1415" lower="3.1415" velocity="1"/>
		<origin rpy="6.255909617295729 3.948159383639452 3.7229714195462145" xyz="0.6558871288496995 0.7560724549748009 0.34690984980424955"/>
	</joint>
	<joint name="24_to_0" type="spherical">
		<parent link="0"/>
		<child link="24"/>
		<axis xyz="0 0 1"/>
		<limit effort="1" upper="-3.1415" lower="3.1415" velocity="1"/>
		<origin rpy="2.2791732312147155 6.13671583941542 1.2029329044022974" xyz="0.07947861641473886 0.297999427620842 0.8497967179941479"/>
	</joint>
	<joint name="35_to_24" type="revolute">
		<parent link="24"/>
		<child link="35"/>
		<axis xyz="0 0 1"/>
		<limit effort="1" upper="-3.1415" lower="3.1415" velocity="1"/>
		<origin rpy="10.243393438197042 5.371854630811844 1.3550456439983716" xyz="0.3822923962062741 0.9874566175113845 0.9820821860147007"/>
	</joint>
	<joint name="46_to_35" type="revolute">
		<parent link="35"/>
		<child link="46"/>
		<axis xyz="0 1 0"/>
		<limit effort="1" upper="-3.1415" lower="3.1415" velocity="1"/>
		<origin rpy="6.162301654842183 1.3832106069790586 5.395604508169425" xyz="0.3993266592088702 0.15059463826679775 0.16064703823713034"/>
	</joint>
	<joint name="47_to_35" type="revolute">
		<parent link="35"/>
		<child link="47"/>
		<axis xyz="0 1 0"/>
		<limit effort="1" upper="-3.1415" lower="3.1415" velocity="1"/>
		<origin rpy="9.243452482263276 1.3832106069790586 5.395604508169425" xyz="0.3993266592088702 0.15059463826679775 0.16064703823713034"/>
	</joint>
	<joint name="38_to_24" type="revolute">
		<parent link="24"/>
		<child link="38"/>
		<axis xyz="0 0 1"/>
		<limit effort="1" upper="-3.1415" lower="3.1415" velocity="1"/>
		<origin rpy="15.365090157295564 5.371854630811844 1.3550456439983716" xyz="0.3822923962062741 0.9874566175113845 0.9820821860147007"/>
	</joint>
	<joint name="49_to_38" type="revolute">
		<parent link="38"/>
		<child link="49"/>
		<axis xyz="0 1 0"/>
		<limit effort="1" upper="-3.1415" lower="3.1415" velocity="1"/>
		<origin rpy="6.162301654842183 1.3832106069790586 5.395604508169425" xyz="0.3993266592088702 0.15059463826679775 0.16064703823713034"/>
	</joint>
	<joint name="410_to_38" type="revolute">
		<parent link="38"/>
		<child link="410"/>
		<axis xyz="0 1 0"/>
		<limit effort="1" upper="-3.1415" lower="3.1415" velocity="1"/>
		<origin rpy="9.243452482263276 1.3832106069790586 5.395604508169425" xyz="0.3993266592088702 0.15059463826679775 0.16064703823713034"/>
	</joint>
	<joint name="211_to_0" type="spherical">
		<parent link="0"/>
		<child link="211"/>
		<axis xyz="0 0 1"/>
		<limit effort="1" upper="-3.1415" lower="3.1415" velocity="1"/>
		<origin rpy="2.7350078774576585 6.13671583941542 1.2029329044022974" xyz="0.07947861641473886 0.297999427620842 0.8497967179941479"/>
	</joint>
	<joint name="312_to_211" type="revolute">
		<parent link="211"/>
		<child link="312"/>
		<axis xyz="0 0 1"/>
		<limit effort="1" upper="-3.1415" lower="3.1415" velocity="1"/>
		<origin rpy="10.243393438197042 5.371854630811844 1.3550456439983716" xyz="0.3822923962062741 0.9874566175113845 0.9820821860147007"/>
	</joint>
	<joint name="413_to_312" type="revolute">
		<parent link="312"/>
		<child link="413"/>
		<axis xyz="0 1 0"/>
		<limit effort="1" upper="-3.1415" lower="3.1415" velocity="1"/>
		<origin rpy="6.162301654842183 1.3832106069790586 5.395604508169425" xyz="0.3993266592088702 0.15059463826679775 0.16064703823713034"/>
	</joint>
	<joint name="414_to_312" type="revolute">
		<parent link="312"/>
		<child link="414"/>
		<axis xyz="0 1 0"/>
		<limit effort="1" upper="-3.1415" lower="3.1415" velocity="1"/>
		<origin rpy="9.243452482263276 1.3832106069790586 5.395604508169425" xyz="0.3993266592088702 0.15059463826679775 0.16064703823713034"/>
	</joint>
	<joint name="315_to_211" type="revolute">
		<parent link="211"/>
		<child link="315"/>
		<axis xyz="0 0 1"/>
		<limit effort="1" upper="-3.1415" lower="3.1415" velocity="1"/>
		<origin rpy="15.365090157295564 5.371854630811844 1.3550456439983716" xyz="0.3822923962062741 0.9874566175113845 0.9820821860147007"/>
	</joint>
	<joint name="416_to_315" type="revolute">
		<parent link="315"/>
		<child link="416"/>
		<axis xyz="0 1 0"/>
		<limit effort="1" upper="-3.1415" lower="3.1415" velocity="1"/>
		<origin rpy="6.162301654842183 1.3832106069790586 5.395604508169425" xyz="0.3993266592088702 0.15059463826679775 0.16064703823713034"/>
	</joint>
	<joint name="417_to_315" type="revolute">
		<parent link="315"/>
		<child link="417"/>
		<axis xyz="0 1 0"/>
		<limit effort="1" upper="-3.1415" lower="3.1415" velocity="1"/>
		<origin rpy="9.243452482263276 1.3832106069790586 5.395604508169425" xyz="0.3993266592088702 0.15059463826679775 0.16064703823713034"/>
	</joint>
	<joint name="518_to_0" type="revolute">
		<parent link="0"/>
		<child link="518"/>
		<axis xyz="0 1 0"/>
		<limit effort="1" upper="-3.1415" lower="3.1415" velocity="1"/>
		<origin rpy="6.3552205673555004 2.0213779144071635 5.280344173804357" xyz="0.44186467407469154 0.6206277780538179 0.4087772514945013"/>
	</joint>
	<joint name="519_to_0" type="revolute">
		<parent link="0"/>
		<child link="519"/>
		<axis xyz="0 1 0"/>
		<limit effort="1" upper="-3.1415" lower="3.1415" velocity="1"/>
		<origin rpy="7.263109219834858 2.0213779144071635 5.280344173804357" xyz="0.44186467407469154 0.6206277780538179 0.4087772514945013"/>
	</joint>
</robot>
