<?xml version="1.0"?><robot name="pepe">
	<link name="0">
		<visual>
			<geometry>
				<cylinder length="2.052335271366942" radius="0.9127046226389154"/>
			</geometry>
		</visual>
		<collision>
			<geometry>
				<cylinder length="2.052335271366942" radius="0.9127046226389154"/>
			</geometry>
		</collision>
		<inertial>
			<mass value="5.371043651051132"/>
			<inertia ixx="0.03" iyy="0.03" izz="0.03" ixy="0" ixz="0" iyx="0"/>
		</inertial>
	</link>
	<link name="11">
		<visual>
			<geometry>
				<cylinder length="2.052335271366942" radius="0.9127046226389154"/>
			</geometry>
		</visual>
		<collision>
			<geometry>
				<cylinder length="2.052335271366942" radius="0.9127046226389154"/>
			</geometry>
		</collision>
		<inertial>
			<mass value="5.371043651051132"/>
			<inertia ixx="0.03" iyy="0.03" izz="0.03" ixy="0" ixz="0" iyx="0"/>
		</inertial>
	</link>
	<link name="12">
		<visual>
			<geometry>
				<cylinder length="2.052335271366942" radius="0.9127046226389154"/>
			</geometry>
		</visual>
		<collision>
			<geometry>
				<cylinder length="2.052335271366942" radius="0.9127046226389154"/>
			</geometry>
		</collision>
		<inertial>
			<mass value="5.371043651051132"/>
			<inertia ixx="0.03" iyy="0.03" izz="0.03" ixy="0" ixz="0" iyx="0"/>
		</inertial>
	</link>
	<joint name="11_to_0" type="revolute">
		<parent link="0"/>
		<child link="11"/>
		<axis xyz="0 0 1"/>
		<limit effort="1" upper="-3.1415" lower="3.1415" velocity="1"/>
		<origin rpy="7.411953740856436 4.876322053624647 2.7448851529332043" xyz="0.5045162168138982 0.37417202270557537 0.47573861974484777"/>
	</joint>
	<joint name="12_to_0" type="revolute">
		<parent link="0"/>
		<child link="12"/>
		<axis xyz="0 0 1"/>
		<limit effort="1" upper="-3.1415" lower="3.1415" velocity="1"/>
		<origin rpy="11.117930611284654 4.876322053624647 2.7448851529332043" xyz="0.5045162168138982 0.37417202270557537 0.47573861974484777"/>
	</joint>
</robot>
