<?xml version="1.0"?><robot name="pepe">
	<link name="0">
		<visual>
			<geometry>
				<cylinder length="2.9780468539074367" radius="0.9999"/>
			</geometry>
		</visual>
		<collision>
			<geometry>
				<cylinder length="2.9780468539074367" radius="0.9999"/>
			</geometry>
		</collision>
		<inertial>
			<mass value="9.353939049816244"/>
			<inertia ixx="0.03" iyy="0.03" izz="0.03" ixy="0" ixz="0" iyx="0"/>
		</inertial>
	</link>
	<link name="11">
		<visual>
			<geometry>
				<cylinder length="2.075448211357434" radius="0.39063922605630597"/>
			</geometry>
		</visual>
		<collision>
			<geometry>
				<cylinder length="2.075448211357434" radius="0.39063922605630597"/>
			</geometry>
		</collision>
		<inertial>
			<mass value="0.9949779934326527"/>
			<inertia ixx="0.03" iyy="0.03" izz="0.03" ixy="0" ixz="0" iyx="0"/>
		</inertial>
	</link>
	<link name="12">
		<visual>
			<geometry>
				<cylinder length="2.075448211357434" radius="0.39063922605630597"/>
			</geometry>
		</visual>
		<collision>
			<geometry>
				<cylinder length="2.075448211357434" radius="0.39063922605630597"/>
			</geometry>
		</collision>
		<inertial>
			<mass value="0.9949779934326527"/>
			<inertia ixx="0.03" iyy="0.03" izz="0.03" ixy="0" ixz="0" iyx="0"/>
		</inertial>
	</link>
	<link name="13">
		<visual>
			<geometry>
				<cylinder length="2.075448211357434" radius="0.39063922605630597"/>
			</geometry>
		</visual>
		<collision>
			<geometry>
				<cylinder length="2.075448211357434" radius="0.39063922605630597"/>
			</geometry>
		</collision>
		<inertial>
			<mass value="0.9949779934326527"/>
			<inertia ixx="0.03" iyy="0.03" izz="0.03" ixy="0" ixz="0" iyx="0"/>
		</inertial>
	</link>
	<joint name="11_to_0" type="revolute">
		<parent link="0"/>
		<child link="11"/>
		<axis xyz="0 0 1"/>
		<limit effort="1" upper="-3.1415" lower="3.1415" velocity="1"/>
		<origin rpy="0.21634403812760747 3.767907355758158 5.407675104821908" xyz="0.3745329695448114 0.7413694365898381 0.750752698584907"/>
	</joint>
	<joint name="12_to_0" type="revolute">
		<parent link="0"/>
		<child link="12"/>
		<axis xyz="0 0 1"/>
		<limit effort="1" upper="-3.1415" lower="3.1415" velocity="1"/>
		<origin rpy="0.3245160571914112 3.767907355758158 5.407675104821908" xyz="0.3745329695448114 0.7413694365898381 0.750752698584907"/>
	</joint>
	<joint name="13_to_0" type="revolute">
		<parent link="0"/>
		<child link="13"/>
		<axis xyz="0 0 1"/>
		<limit effort="1" upper="-3.1415" lower="3.1415" velocity="1"/>
		<origin rpy="0.43268807625521494 3.767907355758158 5.407675104821908" xyz="0.3745329695448114 0.7413694365898381 0.750752698584907"/>
	</joint>
</robot>
