<?xml version="1.0"?><robot name="pepe">
	<link name="0">
		<visual>
			<geometry>
				<cylinder length="2.9780468539074367" radius="0.9999"/>
			</geometry>
		</visual>
		<collision>
			<geometry>
				<cylinder length="2.9780468539074367" radius="0.9999"/>
			</geometry>
		</collision>
		<inertial>
			<mass value="9.353939049816244"/>
			<inertia ixx="0.03" iyy="0.03" izz="0.03" ixy="0" ixz="0" iyx="0"/>
		</inertial>
	</link>
	<link name="11">
		<visual>
			<geometry>
				<cylinder length="0.2146823393420133" radius="0.13395371525019406"/>
			</geometry>
		</visual>
		<collision>
			<geometry>
				<cylinder length="0.2146823393420133" radius="0.13395371525019406"/>
			</geometry>
		</collision>
		<inertial>
			<mass value="0.012101960150834349"/>
			<inertia ixx="0.03" iyy="0.03" izz="0.03" ixy="0" ixz="0" iyx="0"/>
		</inertial>
	</link>
	<link name="12">
		<visual>
			<geometry>
				<cylinder length="0.2146823393420133" radius="0.13395371525019406"/>
			</geometry>
		</visual>
		<collision>
			<geometry>
				<cylinder length="0.2146823393420133" radius="0.13395371525019406"/>
			</geometry>
		</collision>
		<inertial>
			<mass value="0.012101960150834349"/>
			<inertia ixx="0.03" iyy="0.03" izz="0.03" ixy="0" ixz="0" iyx="0"/>
		</inertial>
	</link>
	<joint name="11_to_0" type="revolute">
		<parent link="0"/>
		<child link="11"/>
		<axis xyz="0 1 0"/>
		<limit effort="1" upper="-3.1415" lower="3.1415" velocity="1"/>
		<origin rpy="7.180913294929682 3.6577408159478253 1.5928548321915927" xyz="0.7672908757409634 0.46690638663701267 0.6079189761972736"/>
	</joint>
	<joint name="12_to_0" type="revolute">
		<parent link="0"/>
		<child link="12"/>
		<axis xyz="0 1 0"/>
		<limit effort="1" upper="-3.1415" lower="3.1415" velocity="1"/>
		<origin rpy="10.771369942394523 3.6577408159478253 1.5928548321915927" xyz="0.7672908757409634 0.46690638663701267 0.6079189761972736"/>
	</joint>
</robot>
