<?xml version="1.0"?><robot name="pepe">
	<link name="0">
		<visual>
			<geometry>
				<cylinder length="0.7893298455281619" radius="0.4449545980872709"/>
			</geometry>
		</visual>
		<collision>
			<geometry>
				<cylinder length="0.7893298455281619" radius="0.4449545980872709"/>
			</geometry>
		</collision>
		<inertial>
			<mass value="0.4909528609240759"/>
			<inertia ixx="0.03" iyy="0.03" izz="0.03" ixy="0" ixz="0" iyx="0"/>
		</inertial>
	</link>
	<link name="11">
		<visual>
			<geometry>
				<cylinder length="2.8219324425915286" radius="0.2802727606231159"/>
			</geometry>
		</visual>
		<collision>
			<geometry>
				<cylinder length="2.8219324425915286" radius="0.2802727606231159"/>
			</geometry>
		</collision>
		<inertial>
			<mass value="0.6963992066119021"/>
			<inertia ixx="0.03" iyy="0.03" izz="0.03" ixy="0" ixz="0" iyx="0"/>
		</inertial>
	</link>
	<link name="12">
		<visual>
			<geometry>
				<cylinder length="2.8219324425915286" radius="0.2802727606231159"/>
			</geometry>
		</visual>
		<collision>
			<geometry>
				<cylinder length="2.8219324425915286" radius="0.2802727606231159"/>
			</geometry>
		</collision>
		<inertial>
			<mass value="0.6963992066119021"/>
			<inertia ixx="0.03" iyy="0.03" izz="0.03" ixy="0" ixz="0" iyx="0"/>
		</inertial>
	</link>
	<joint name="11_to_0" type="revolute">
		<parent link="0"/>
		<child link="11"/>
		<axis xyz="0 0 1"/>
		<limit effort="1" upper="-3.1415" lower="3.1415" velocity="1"/>
		<origin rpy="5.8952369049848725 3.3106343739814474 4.297380134307079" xyz="0.8262303950921 0.8226883777035289 0.6965361425547957"/>
	</joint>
	<joint name="12_to_0" type="revolute">
		<parent link="0"/>
		<child link="12"/>
		<axis xyz="0 0 1"/>
		<limit effort="1" upper="-3.1415" lower="3.1415" velocity="1"/>
		<origin rpy="8.842855357477308 3.3106343739814474 4.297380134307079" xyz="0.8262303950921 0.8226883777035289 0.6965361425547957"/>
	</joint>
</robot>
