<?xml version="1.0"?><robot name="pepe">
	<link name="0">
		<visual>
			<geometry>
				<cylinder length="2.2897371470123566" radius="0.7030700459111242"/>
			</geometry>
		</visual>
		<collision>
			<geometry>
				<cylinder length="2.2897371470123566" radius="0.7030700459111242"/>
			</geometry>
		</collision>
		<inertial>
			<mass value="3.5557620726981525"/>
			<inertia ixx="0.03" iyy="0.03" izz="0.03" ixy="0" ixz="0" iyx="0"/>
		</inertial>
	</link>
	<link name="11">
		<visual>
			<geometry>
				<cylinder length="2.6780468539074365" radius="0.9999"/>
			</geometry>
		</visual>
		<collision>
			<geometry>
				<cylinder length="2.6780468539074365" radius="0.9999"/>
			</geometry>
		</collision>
		<inertial>
			<mass value="8.411649739873743"/>
			<inertia ixx="0.03" iyy="0.03" izz="0.03" ixy="0" ixz="0" iyx="0"/>
		</inertial>
	</link>
	<link name="22">
		<visual>
			<geometry>
				<cylinder length="1.0461836865175318" radius="0.776862317618009"/>
			</geometry>
		</visual>
		<collision>
			<geometry>
				<cylinder length="1.0461836865175318" radius="0.776862317618009"/>
			</geometry>
		</collision>
		<inertial>
			<mass value="1.983562679968455"/>
			<inertia ixx="0.03" iyy="0.03" izz="0.03" ixy="0" ixz="0" iyx="0"/>
		</inertial>
	</link>
	<joint name="11_to_0" type="revolute">
		<parent link="0"/>
		<child link="11"/>
		<axis xyz="0 1 0"/>
		<limit effort="1" upper="-3.1415" lower="3.1415" velocity="1"/>
		<origin rpy="0.7978502867217495 6.225550231962962 1.5650392050855029" xyz="0.1319503410670193 0.058181755163629334 0.8637086315317808"/>
	</joint>
	<joint name="22_to_11" type="spherical">
		<parent link="11"/>
		<child link="22"/>
		<axis xyz="1 0 0"/>
		<limit effort="1" upper="-3.1415" lower="3.1415" velocity="1"/>
		<origin rpy="3.5466683883543815 1.0091730243176926 2.5959752496388906" xyz="0.6612982766976728 0.23886698680982965 0.2789055991869269"/>
	</joint>
</robot>
