<?xml version="1.0"?><robot name="pepe">
	<link name="0">
		<visual>
			<geometry>
				<cylinder length="2.9780468539074367" radius="0.9999"/>
			</geometry>
		</visual>
		<collision>
			<geometry>
				<cylinder length="2.9780468539074367" radius="0.9999"/>
			</geometry>
		</collision>
		<inertial>
			<mass value="9.353939049816244"/>
			<inertia ixx="0.03" iyy="0.03" izz="0.03" ixy="0" ixz="0" iyx="0"/>
		</inertial>
	</link>
	<link name="11">
		<visual>
			<geometry>
				<cylinder length="2.294431198548997" radius="0.6769759616659846"/>
			</geometry>
		</visual>
		<collision>
			<geometry>
				<cylinder length="2.294431198548997" radius="0.6769759616659846"/>
			</geometry>
		</collision>
		<inertial>
			<mass value="3.3034779152019746"/>
			<inertia ixx="0.03" iyy="0.03" izz="0.03" ixy="0" ixz="0" iyx="0"/>
		</inertial>
	</link>
	<link name="12">
		<visual>
			<geometry>
				<cylinder length="2.294431198548997" radius="0.6769759616659846"/>
			</geometry>
		</visual>
		<collision>
			<geometry>
				<cylinder length="2.294431198548997" radius="0.6769759616659846"/>
			</geometry>
		</collision>
		<inertial>
			<mass value="3.3034779152019746"/>
			<inertia ixx="0.03" iyy="0.03" izz="0.03" ixy="0" ixz="0" iyx="0"/>
		</inertial>
	</link>
	<joint name="11_to_0" type="revolute">
		<parent link="0"/>
		<child link="11"/>
		<axis xyz="0 1 0"/>
		<limit effort="1" upper="-3.1415" lower="3.1415" velocity="1"/>
		<origin rpy="6.502832836457893 3.090190378513591 2.911190276195395" xyz="0.5297463771887722 0.07326856639636481 0.6681311235131618"/>
	</joint>
	<joint name="12_to_0" type="revolute">
		<parent link="0"/>
		<child link="12"/>
		<axis xyz="0 1 0"/>
		<limit effort="1" upper="-3.1415" lower="3.1415" velocity="1"/>
		<origin rpy="9.75424925468684 3.090190378513591 2.911190276195395" xyz="0.5297463771887722 0.07326856639636481 0.6681311235131618"/>
	</joint>
</robot>
