<?xml version="1.0"?><robot name="pepe">
	<link name="0">
		<visual>
			<geometry>
				<cylinder length="1.8086877259233258" radius="0.6363854840141339"/>
			</geometry>
		</visual>
		<collision>
			<geometry>
				<cylinder length="1.8086877259233258" radius="0.6363854840141339"/>
			</geometry>
		</collision>
		<inertial>
			<mass value="2.3011980307454967"/>
			<inertia ixx="0.03" iyy="0.03" izz="0.03" ixy="0" ixz="0" iyx="0"/>
		</inertial>
	</link>
	<link name="11">
		<visual>
			<geometry>
				<cylinder length="1.8086877259233258" radius="0.6363854840141339"/>
			</geometry>
		</visual>
		<collision>
			<geometry>
				<cylinder length="1.8086877259233258" radius="0.6363854840141339"/>
			</geometry>
		</collision>
		<inertial>
			<mass value="2.3011980307454967"/>
			<inertia ixx="0.03" iyy="0.03" izz="0.03" ixy="0" ixz="0" iyx="0"/>
		</inertial>
	</link>
	<link name="12">
		<visual>
			<geometry>
				<cylinder length="1.8086877259233258" radius="0.6363854840141339"/>
			</geometry>
		</visual>
		<collision>
			<geometry>
				<cylinder length="1.8086877259233258" radius="0.6363854840141339"/>
			</geometry>
		</collision>
		<inertial>
			<mass value="2.3011980307454967"/>
			<inertia ixx="0.03" iyy="0.03" izz="0.03" ixy="0" ixz="0" iyx="0"/>
		</inertial>
	</link>
	<joint name="11_to_0" type="revolute">
		<parent link="0"/>
		<child link="11"/>
		<axis xyz="0 1 0"/>
		<limit effort="1" upper="-3.1415" lower="3.1415" velocity="1"/>
		<origin rpy="0.4823313525006561 5.676986218241764 2.160913624791952" xyz="0.6693401969231848 0.10861495855467818 0.3415628780390997"/>
	</joint>
	<joint name="12_to_0" type="revolute">
		<parent link="0"/>
		<child link="12"/>
		<axis xyz="0 1 0"/>
		<limit effort="1" upper="-3.1415" lower="3.1415" velocity="1"/>
		<origin rpy="0.7234970287509842 5.676986218241764 2.160913624791952" xyz="0.6693401969231848 0.10861495855467818 0.3415628780390997"/>
	</joint>
</robot>
