<?xml version="1.0"?><robot name="pepe">
	<link name="0">
		<visual>
			<geometry>
				<cylinder length="1.3303240535078822" radius="0.3058566576238244"/>
			</geometry>
		</visual>
		<collision>
			<geometry>
				<cylinder length="1.3303240535078822" radius="0.3058566576238244"/>
			</geometry>
		</collision>
		<inertial>
			<mass value="0.3909697826612453"/>
			<inertia ixx="0.03" iyy="0.03" izz="0.03" ixy="0" ixz="0" iyx="0"/>
		</inertial>
	</link>
	<link name="11">
		<visual>
			<geometry>
				<cylinder length="2.2455110286492643" radius="0.43266176928651967"/>
			</geometry>
		</visual>
		<collision>
			<geometry>
				<cylinder length="2.2455110286492643" radius="0.43266176928651967"/>
			</geometry>
		</collision>
		<inertial>
			<mass value="1.320572073604105"/>
			<inertia ixx="0.03" iyy="0.03" izz="0.03" ixy="0" ixz="0" iyx="0"/>
		</inertial>
	</link>
	<link name="12">
		<visual>
			<geometry>
				<cylinder length="2.2455110286492643" radius="0.43266176928651967"/>
			</geometry>
		</visual>
		<collision>
			<geometry>
				<cylinder length="2.2455110286492643" radius="0.43266176928651967"/>
			</geometry>
		</collision>
		<inertial>
			<mass value="1.320572073604105"/>
			<inertia ixx="0.03" iyy="0.03" izz="0.03" ixy="0" ixz="0" iyx="0"/>
		</inertial>
	</link>
	<joint name="11_to_0" type="revolute">
		<parent link="0"/>
		<child link="11"/>
		<axis xyz="0 1 0"/>
		<limit effort="1" upper="-3.1415" lower="3.1415" velocity="1"/>
		<origin rpy="12.079475270275633 5.634092577633196 0.9553492627158846" xyz="0.12710202494398815 0.7279605242954719 0.7173072026098758"/>
	</joint>
	<joint name="12_to_0" type="revolute">
		<parent link="0"/>
		<child link="12"/>
		<axis xyz="0 1 0"/>
		<limit effort="1" upper="-3.1415" lower="3.1415" velocity="1"/>
		<origin rpy="18.11921290541345 5.634092577633196 0.9553492627158846" xyz="0.12710202494398815 0.7279605242954719 0.7173072026098758"/>
	</joint>
</robot>
