<?xml version="1.0"?><robot name="pepe">
	<link name="0">
		<visual>
			<geometry>
				<cylinder length="2.9780468539074367" radius="0.9999"/>
			</geometry>
		</visual>
		<collision>
			<geometry>
				<cylinder length="2.9780468539074367" radius="0.9999"/>
			</geometry>
		</collision>
		<inertial>
			<mass value="9.353939049816244"/>
			<inertia ixx="0.03" iyy="0.03" izz="0.03" ixy="0" ixz="0" iyx="0"/>
		</inertial>
	</link>
	<link name="11">
		<visual>
			<geometry>
				<cylinder length="0.5702286811228139" radius="0.3435822541894309"/>
			</geometry>
		</visual>
		<collision>
			<geometry>
				<cylinder length="0.5702286811228139" radius="0.3435822541894309"/>
			</geometry>
		</collision>
		<inertial>
			<mass value="0.21147565539283159"/>
			<inertia ixx="0.03" iyy="0.03" izz="0.03" ixy="0" ixz="0" iyx="0"/>
		</inertial>
	</link>
	<link name="12">
		<visual>
			<geometry>
				<cylinder length="0.5702286811228139" radius="0.3435822541894309"/>
			</geometry>
		</visual>
		<collision>
			<geometry>
				<cylinder length="0.5702286811228139" radius="0.3435822541894309"/>
			</geometry>
		</collision>
		<inertial>
			<mass value="0.21147565539283159"/>
			<inertia ixx="0.03" iyy="0.03" izz="0.03" ixy="0" ixz="0" iyx="0"/>
		</inertial>
	</link>
	<joint name="11_to_0" type="revolute">
		<parent link="0"/>
		<child link="11"/>
		<axis xyz="1 0 0"/>
		<limit effort="1" upper="-3.1415" lower="3.1415" velocity="1"/>
		<origin rpy="11.399299152947133 1.794067843027246 1.3928099551993185" xyz="0.6212625768849402 0.3805403696735459 0.9772863457954744"/>
	</joint>
	<joint name="12_to_0" type="revolute">
		<parent link="0"/>
		<child link="12"/>
		<axis xyz="1 0 0"/>
		<limit effort="1" upper="-3.1415" lower="3.1415" velocity="1"/>
		<origin rpy="17.098948729420698 1.794067843027246 1.3928099551993185" xyz="0.6212625768849402 0.3805403696735459 0.9772863457954744"/>
	</joint>
</robot>
