<?xml version="1.0"?><robot name="pepe">
	<link name="0">
		<visual>
			<geometry>
				<cylinder length="2.052335271366942" radius="0.9127046226389154"/>
			</geometry>
		</visual>
		<collision>
			<geometry>
				<cylinder length="2.052335271366942" radius="0.9127046226389154"/>
			</geometry>
		</collision>
		<inertial>
			<mass value="5.371043651051132"/>
			<inertia ixx="0.03" iyy="0.03" izz="0.03" ixy="0" ixz="0" iyx="0"/>
		</inertial>
	</link>
	<link name="11">
		<visual>
			<geometry>
				<cylinder length="1.5032245014012546" radius="0.5461271337411946"/>
			</geometry>
		</visual>
		<collision>
			<geometry>
				<cylinder length="1.5032245014012546" radius="0.5461271337411946"/>
			</geometry>
		</collision>
		<inertial>
			<mass value="1.4085141930628478"/>
			<inertia ixx="0.03" iyy="0.03" izz="0.03" ixy="0" ixz="0" iyx="0"/>
		</inertial>
	</link>
	<link name="12">
		<visual>
			<geometry>
				<cylinder length="1.5032245014012546" radius="0.5461271337411946"/>
			</geometry>
		</visual>
		<collision>
			<geometry>
				<cylinder length="1.5032245014012546" radius="0.5461271337411946"/>
			</geometry>
		</collision>
		<inertial>
			<mass value="1.4085141930628478"/>
			<inertia ixx="0.03" iyy="0.03" izz="0.03" ixy="0" ixz="0" iyx="0"/>
		</inertial>
	</link>
	<link name="13">
		<visual>
			<geometry>
				<cylinder length="1.5032245014012546" radius="0.5461271337411946"/>
			</geometry>
		</visual>
		<collision>
			<geometry>
				<cylinder length="1.5032245014012546" radius="0.5461271337411946"/>
			</geometry>
		</collision>
		<inertial>
			<mass value="1.4085141930628478"/>
			<inertia ixx="0.03" iyy="0.03" izz="0.03" ixy="0" ixz="0" iyx="0"/>
		</inertial>
	</link>
	<joint name="11_to_0" type="revolute">
		<parent link="0"/>
		<child link="11"/>
		<axis xyz="0 0 1"/>
		<limit effort="1" upper="-3.1415" lower="3.1415" velocity="1"/>
		<origin rpy="8.729632553423173 4.249201166298755 2.1642156726839814" xyz="0.15022150851857297 0.7642208410788358 0.4845052357836219"/>
	</joint>
	<joint name="12_to_0" type="revolute">
		<parent link="0"/>
		<child link="12"/>
		<axis xyz="0 0 1"/>
		<limit effort="1" upper="-3.1415" lower="3.1415" velocity="1"/>
		<origin rpy="13.094448830134759 4.249201166298755 2.1642156726839814" xyz="0.15022150851857297 0.7642208410788358 0.4845052357836219"/>
	</joint>
	<joint name="13_to_0" type="revolute">
		<parent link="0"/>
		<child link="13"/>
		<axis xyz="0 0 1"/>
		<limit effort="1" upper="-3.1415" lower="3.1415" velocity="1"/>
		<origin rpy="17.459265106846345 4.249201166298755 2.1642156726839814" xyz="0.15022150851857297 0.7642208410788358 0.4845052357836219"/>
	</joint>
</robot>
