<?xml version="1.0"?><robot name="pepe">
	<link name="0">
		<visual>
			<geometry>
				<cylinder length="2.052335271366942" radius="0.9127046226389154"/>
			</geometry>
		</visual>
		<collision>
			<geometry>
				<cylinder length="2.052335271366942" radius="0.9127046226389154"/>
			</geometry>
		</collision>
		<inertial>
			<mass value="5.371043651051132"/>
			<inertia ixx="0.03" iyy="0.03" izz="0.03" ixy="0" ixz="0" iyx="0"/>
		</inertial>
	</link>
	<link name="11">
		<visual>
			<geometry>
				<cylinder length="2.5823645629742993" radius="0.23398266248795874"/>
			</geometry>
		</visual>
		<collision>
			<geometry>
				<cylinder length="2.5823645629742993" radius="0.23398266248795874"/>
			</geometry>
		</collision>
		<inertial>
			<mass value="0.4441552327825664"/>
			<inertia ixx="0.03" iyy="0.03" izz="0.03" ixy="0" ixz="0" iyx="0"/>
		</inertial>
	</link>
	<link name="12">
		<visual>
			<geometry>
				<cylinder length="2.5823645629742993" radius="0.23398266248795874"/>
			</geometry>
		</visual>
		<collision>
			<geometry>
				<cylinder length="2.5823645629742993" radius="0.23398266248795874"/>
			</geometry>
		</collision>
		<inertial>
			<mass value="0.4441552327825664"/>
			<inertia ixx="0.03" iyy="0.03" izz="0.03" ixy="0" ixz="0" iyx="0"/>
		</inertial>
	</link>
	<joint name="11_to_0" type="revolute">
		<parent link="0"/>
		<child link="11"/>
		<axis xyz="1 0 0"/>
		<limit effort="1" upper="-3.1415" lower="3.1415" velocity="1"/>
		<origin rpy="6.169183716290176 2.8041894148144473 3.944862445753058" xyz="0.06346158879997266 0.20921846391114063 0.8103165663829949"/>
	</joint>
	<joint name="12_to_0" type="revolute">
		<parent link="0"/>
		<child link="12"/>
		<axis xyz="1 0 0"/>
		<limit effort="1" upper="-3.1415" lower="3.1415" velocity="1"/>
		<origin rpy="9.253775574435263 2.8041894148144473 3.944862445753058" xyz="0.06346158879997266 0.20921846391114063 0.8103165663829949"/>
	</joint>
</robot>
