<?xml version="1.0"?><robot name="pepe">
	<link name="0">
		<visual>
			<geometry>
				<cylinder length="2.052335271366942" radius="0.9127046226389154"/>
			</geometry>
		</visual>
		<collision>
			<geometry>
				<cylinder length="2.052335271366942" radius="0.9127046226389154"/>
			</geometry>
		</collision>
		<inertial>
			<mass value="5.371043651051132"/>
			<inertia ixx="0.03" iyy="0.03" izz="0.03" ixy="0" ixz="0" iyx="0"/>
		</inertial>
	</link>
	<link name="11">
		<visual>
			<geometry>
				<cylinder length="0.04355805341238683" radius="0.6743155374042407"/>
			</geometry>
		</visual>
		<collision>
			<geometry>
				<cylinder length="0.04355805341238683" radius="0.6743155374042407"/>
			</geometry>
		</collision>
		<inertial>
			<mass value="0.06222210067437925"/>
			<inertia ixx="0.03" iyy="0.03" izz="0.03" ixy="0" ixz="0" iyx="0"/>
		</inertial>
	</link>
	<link name="12">
		<visual>
			<geometry>
				<cylinder length="0.04355805341238683" radius="0.6743155374042407"/>
			</geometry>
		</visual>
		<collision>
			<geometry>
				<cylinder length="0.04355805341238683" radius="0.6743155374042407"/>
			</geometry>
		</collision>
		<inertial>
			<mass value="0.06222210067437925"/>
			<inertia ixx="0.03" iyy="0.03" izz="0.03" ixy="0" ixz="0" iyx="0"/>
		</inertial>
	</link>
	<link name="13">
		<visual>
			<geometry>
				<cylinder length="0.04355805341238683" radius="0.6743155374042407"/>
			</geometry>
		</visual>
		<collision>
			<geometry>
				<cylinder length="0.04355805341238683" radius="0.6743155374042407"/>
			</geometry>
		</collision>
		<inertial>
			<mass value="0.06222210067437925"/>
			<inertia ixx="0.03" iyy="0.03" izz="0.03" ixy="0" ixz="0" iyx="0"/>
		</inertial>
	</link>
	<joint name="11_to_0" type="revolute">
		<parent link="0"/>
		<child link="11"/>
		<axis xyz="0 0 1"/>
		<limit effort="1" upper="-3.1415" lower="3.1415" velocity="1"/>
		<origin rpy="3.665627021291142 3.4461957487232304 3.601878256724205" xyz="0.7079929209110009 0.6897527556007799 0.33257736655265435"/>
	</joint>
	<joint name="12_to_0" type="revolute">
		<parent link="0"/>
		<child link="12"/>
		<axis xyz="0 0 1"/>
		<limit effort="1" upper="-3.1415" lower="3.1415" velocity="1"/>
		<origin rpy="5.498440531936713 3.4461957487232304 3.601878256724205" xyz="0.7079929209110009 0.6897527556007799 0.33257736655265435"/>
	</joint>
	<joint name="13_to_0" type="revolute">
		<parent link="0"/>
		<child link="13"/>
		<axis xyz="0 0 1"/>
		<limit effort="1" upper="-3.1415" lower="3.1415" velocity="1"/>
		<origin rpy="7.331254042582284 3.4461957487232304 3.601878256724205" xyz="0.7079929209110009 0.6897527556007799 0.33257736655265435"/>
	</joint>
</robot>
