<?xml version="1.0"?><robot name="pepe">
	<link name="0">
		<visual>
			<geometry>
				<cylinder length="0.7893298455281619" radius="0.4449545980872709"/>
			</geometry>
		</visual>
		<collision>
			<geometry>
				<cylinder length="0.7893298455281619" radius="0.4449545980872709"/>
			</geometry>
		</collision>
		<inertial>
			<mass value="0.4909528609240759"/>
			<inertia ixx="0.03" iyy="0.03" izz="0.03" ixy="0" ixz="0" iyx="0"/>
		</inertial>
	</link>
	<link name="11">
		<visual>
			<geometry>
				<cylinder length="2.8841292678793375" radius="0.7542216174333798"/>
			</geometry>
		</visual>
		<collision>
			<geometry>
				<cylinder length="2.8841292678793375" radius="0.7542216174333798"/>
			</geometry>
		</collision>
		<inertial>
			<mass value="5.154215188081768"/>
			<inertia ixx="0.03" iyy="0.03" izz="0.03" ixy="0" ixz="0" iyx="0"/>
		</inertial>
	</link>
	<joint name="11_to_0" type="revolute">
		<parent link="0"/>
		<child link="11"/>
		<axis xyz="1 0 0"/>
		<limit effort="1" upper="-3.1415" lower="3.1415" velocity="1"/>
		<origin rpy="11.11280493169299 0.09283493884436328 0.3982078433867569" xyz="0.5511662130542769 0.30373143222696186 0.19728006789757924"/>
	</joint>
</robot>
