<?xml version="1.0"?><robot name="pepe">
	<link name="0">
		<visual>
			<geometry>
				<cylinder length="0.6733912339158112" radius="0.6313124805478552"/>
			</geometry>
		</visual>
		<collision>
			<geometry>
				<cylinder length="0.6733912339158112" radius="0.6313124805478552"/>
			</geometry>
		</collision>
		<inertial>
			<mass value="0.8431524015623091"/>
			<inertia ixx="0.03" iyy="0.03" izz="0.03" ixy="0" ixz="0" iyx="0"/>
		</inertial>
	</link>
	<link name="11">
		<visual>
			<geometry>
				<cylinder length="0.5824397545460502" radius="0.08170866866614057"/>
			</geometry>
		</visual>
		<collision>
			<geometry>
				<cylinder length="0.5824397545460502" radius="0.08170866866614057"/>
			</geometry>
		</collision>
		<inertial>
			<mass value="0.012216228613731638"/>
			<inertia ixx="0.03" iyy="0.03" izz="0.03" ixy="0" ixz="0" iyx="0"/>
		</inertial>
	</link>
	<link name="12">
		<visual>
			<geometry>
				<cylinder length="0.5824397545460502" radius="0.08170866866614057"/>
			</geometry>
		</visual>
		<collision>
			<geometry>
				<cylinder length="0.5824397545460502" radius="0.08170866866614057"/>
			</geometry>
		</collision>
		<inertial>
			<mass value="0.012216228613731638"/>
			<inertia ixx="0.03" iyy="0.03" izz="0.03" ixy="0" ixz="0" iyx="0"/>
		</inertial>
	</link>
	<joint name="11_to_0" type="revolute">
		<parent link="0"/>
		<child link="11"/>
		<axis xyz="1 0 0"/>
		<limit effort="1" upper="-3.1415" lower="3.1415" velocity="1"/>
		<origin rpy="4.058591580466723 4.261621733613718 0.22681187016657334" xyz="0.9530981933077791 0.19771832990199634 0.6297036097793535"/>
	</joint>
	<joint name="12_to_0" type="revolute">
		<parent link="0"/>
		<child link="12"/>
		<axis xyz="1 0 0"/>
		<limit effort="1" upper="-3.1415" lower="3.1415" velocity="1"/>
		<origin rpy="6.087887370700085 4.261621733613718 0.22681187016657334" xyz="0.9530981933077791 0.19771832990199634 0.6297036097793535"/>
	</joint>
</robot>
