<?xml version="1.0"?><robot name="pepe">
	<link name="0">
		<visual>
			<geometry>
				<cylinder length="1.3659893883272214" radius="0.6836311533579179"/>
			</geometry>
		</visual>
		<collision>
			<geometry>
				<cylinder length="1.3659893883272214" radius="0.6836311533579179"/>
			</geometry>
		</collision>
		<inertial>
			<mass value="2.0055841520331796"/>
			<inertia ixx="0.03" iyy="0.03" izz="0.03" ixy="0" ixz="0" iyx="0"/>
		</inertial>
	</link>
	<link name="11">
		<visual>
			<geometry>
				<cylinder length="0.7484492312171249" radius="0.48318284140159073"/>
			</geometry>
		</visual>
		<collision>
			<geometry>
				<cylinder length="0.7484492312171249" radius="0.48318284140159073"/>
			</geometry>
		</collision>
		<inertial>
			<mass value="0.5489530799968464"/>
			<inertia ixx="0.03" iyy="0.03" izz="0.03" ixy="0" ixz="0" iyx="0"/>
		</inertial>
	</link>
	<joint name="11_to_0" type="revolute">
		<parent link="0"/>
		<child link="11"/>
		<axis xyz="1 0 0"/>
		<limit effort="1" upper="-3.1415" lower="3.1415" velocity="1"/>
		<origin rpy="4.151929505198383 4.832124504265251 5.194780699737973" xyz="0.22487902785236627 0.43760318945247034 0.4595920699586823"/>
	</joint>
</robot>
