<?xml version="1.0"?><robot name="pepe">
	<link name="0">
		<visual>
			<geometry>
				<cylinder length="1.5623497481631918" radius="0.6261912174236801"/>
			</geometry>
		</visual>
		<collision>
			<geometry>
				<cylinder length="1.5623497481631918" radius="0.6261912174236801"/>
			</geometry>
		</collision>
		<inertial>
			<mass value="1.924607078642674"/>
			<inertia ixx="0.03" iyy="0.03" izz="0.03" ixy="0" ixz="0" iyx="0"/>
		</inertial>
	</link>
	<link name="11">
		<visual>
			<geometry>
				<cylinder length="1.2193663251809304" radius="0.6711037832164134"/>
			</geometry>
		</visual>
		<collision>
			<geometry>
				<cylinder length="1.2193663251809304" radius="0.6711037832164134"/>
			</geometry>
		</collision>
		<inertial>
			<mass value="1.7252953186923625"/>
			<inertia ixx="0.03" iyy="0.03" izz="0.03" ixy="0" ixz="0" iyx="0"/>
		</inertial>
	</link>
	<link name="12">
		<visual>
			<geometry>
				<cylinder length="1.2193663251809304" radius="0.6711037832164134"/>
			</geometry>
		</visual>
		<collision>
			<geometry>
				<cylinder length="1.2193663251809304" radius="0.6711037832164134"/>
			</geometry>
		</collision>
		<inertial>
			<mass value="1.7252953186923625"/>
			<inertia ixx="0.03" iyy="0.03" izz="0.03" ixy="0" ixz="0" iyx="0"/>
		</inertial>
	</link>
	<link name="13">
		<visual>
			<geometry>
				<cylinder length="1.2193663251809304" radius="0.6711037832164134"/>
			</geometry>
		</visual>
		<collision>
			<geometry>
				<cylinder length="1.2193663251809304" radius="0.6711037832164134"/>
			</geometry>
		</collision>
		<inertial>
			<mass value="1.7252953186923625"/>
			<inertia ixx="0.03" iyy="0.03" izz="0.03" ixy="0" ixz="0" iyx="0"/>
		</inertial>
	</link>
	<joint name="11_to_0" type="revolute">
		<parent link="0"/>
		<child link="11"/>
		<axis xyz="0 0 1"/>
		<limit effort="1" upper="-3.1415" lower="3.1415" velocity="1"/>
		<origin rpy="9.027699134877802 5.583971434492269 4.7340967613393" xyz="0.606865204064336 0.7262203353889456 0.9999"/>
	</joint>
	<joint name="12_to_0" type="revolute">
		<parent link="0"/>
		<child link="12"/>
		<axis xyz="0 0 1"/>
		<limit effort="1" upper="-3.1415" lower="3.1415" velocity="1"/>
		<origin rpy="13.541548702316703 5.583971434492269 4.7340967613393" xyz="0.606865204064336 0.7262203353889456 0.9999"/>
	</joint>
	<joint name="13_to_0" type="revolute">
		<parent link="0"/>
		<child link="13"/>
		<axis xyz="0 0 1"/>
		<limit effort="1" upper="-3.1415" lower="3.1415" velocity="1"/>
		<origin rpy="18.055398269755603 5.583971434492269 4.7340967613393" xyz="0.606865204064336 0.7262203353889456 0.9999"/>
	</joint>
</robot>
